Workbook

Sheet Tarifas e Resoluções
B2: Concessionárias | C2: ANTERIOR | H2: ATUAL | O2: Data de Reajuste
C3: PONTA | E3: FORA PONTA | H3: PONTA | J3: FORA PONTA
C4: TUSD | D4: TE | E4: TUSD | F4: TE | G4: Resolução | H4: TUSD | I4: TE | J4: TUSD | K4: TE | L4: Resolução | M4: Tipo de Reajuste
B5: Equatorial PA | C5: 2.58258 | D5: 0.43857 | E5: 0.15186 | F5: 0.26893 | G5: RES. 3.507, de 05/08/2025 | H5: 2.52047 | I5: 0.4913 | J5: 0.19197 | K5: 0.28528 | L5: RES. 3.608, de 15/09/2026 | M5: Reajuste | N5: =IF(L5="",MID(G5,FIND("de ",G5)+3,10),MID(L5,FIND("de ",L5)+3,10)) -> 15/09/2026 | O5: =TODAY()-N5 -> 7
B6: Energisa TO (ETO) | C6: 2.03801 | D6: 0.44315 | E6: 0.10693 | F6: 0.27255 | G6: RES. 3.479, de 01/07/2025 | H6: 2.08797 | I6: 0.48892 | J6: 0.1325 | K6: 0.29608 | L6: RES. 3.593, de 30/06/2026 | M6: Reajuste | N6: =IF(L6="",MID(G6,FIND("de ",G6)+3,10),MID(L6,FIND("de ",L6)+3,10)) -> 30/06/2026 | O6: =TODAY()-N6 -> 84
B7: Equatorial MA | C7: 2.37747 | D7: 0.43069 | E7: 0.11615 | F7: 0.26656 | G7: RES. 3.512, de 26/08/2025 | H7: 2.39324 | I7: 0.47206 | J7: 0.15513 | K7: 0.27606 | L7: RES. 3.604, de 24/08/2026 | M7: Reajuste | N7: =IF(L7="",MID(G7,FIND("de ",G7)+3,10),MID(L7,FIND("de ",L7)+3,10)) -> 24/08/2026 | O7: =TODAY()-N7 -> 29
B8: Energisa AC (EAC) | C8: 2.75366 | D8: 0.28833 | E8: 0.143633 | F8: 0.14153 | G8: RES. 3.556, de 09/12/2025 | N8: =IF(L8="",MID(G8,FIND("de ",G8)+3,10),MID(L8,FIND("de ",L8)+3,10)) -> 09/12/2025 | O8: =TODAY()-N8 -> 287
B9: Energisa RO (ERO) | C9: 2.5299 | D9: 0.3858 | E9: 0.15417 | F9: 0.20039 | G9: RES. 3.560, de 09/12/2025 | N9: =IF(L9="",MID(G9,FIND("de ",G9)+3,10),MID(L9,FIND("de ",L9)+3,10)) -> 09/12/2025 | O9: =TODAY()-N9 -> 287
B10: LIGHT (LIGHT SESA) | C10: 1.12281 | D10: 0.46099 | E10: 0.1615 | F10: 0.29436 | G10: RES. 3.474, de 17/06/2025 | H10: 1.17632 | I10: 0.43742 | J10: 0.21501 | K10: 0.28537 | L10: RES. 3.571, de 10/03/2026 | M10: Reajuste | N10: =IF(L10="",MID(G10,FIND("de ",G10)+3,10),MID(L10,FIND("de ",L10)+3,10)) -> 10/03/2026 | O10: =TODAY()-N10 -> 196
B11: Energisa MT (EMT) | C11: 1.71329 | D11: 0.47966 | E11: 0.13105 | F11: 0.28462 | G11: RES. 3.440, de 01/04/2025 | H11: 1.80798 | I11: 0.4892 | J11: 0.16594 | K11: 0.28446 | L11: RES. 3.581, de 22/04/2026 | M11: Reajuste | N11: =IF(L11="",MID(G11,FIND("de ",G11)+3,10),MID(L11,FIND("de ",L11)+3,10)) -> 22/04/2026 | O11: =TODAY()-N11 -> 153
B12: Energisa PB (EPB) | C12: 1.28154 | D12: 0.40487 | E12: 0.09851 | F12: 0.2407 | G12: RES. 3.518, de 26/08/2025 | H12: 1.2899 | I12: 0.42819 | J12: 0.12652 | K12: 0.24537 | L12: RES. 3.603, de 24/08/2026 | M12: Reajuste | N12: =IF(L12="",MID(G12,FIND("de ",G12)+3,10),MID(L12,FIND("de ",L12)+3,10)) -> 24/08/2026 | O12: =TODAY()-N12 -> 29
B13: SULGIPE | C13: 1.70294 | D13: 0.35235 | E13: 0.08493 | F13: 0.21751 | G13: RES. 3.453, de 20/05/2025 | H13: 1.71878 | I13: 0.36613 | J13: 0.12233 | K13: 0.22247 | L13: RES. 3.453, de 20/05/2026 | M13: Reajuste | N13: =IF(L13="",MID(G13,FIND("de ",G13)+3,10),MID(L13,FIND("de ",L13)+3,10)) -> 20/05/2026 | O13: =TODAY()-N13 -> 125
B14: Neoenergia PE | C14: 1.24441 | D14: 0.43671 | E14: 0.09468 | F14: 0.2661 | G14: RES. 3.451, de 29/04/2025 | H14: 1.12806 | I14: 0.4377 | J14: 0.12359 | K14: 0.25527 | L14: RES. 3.583, de 28/04/2026 | M14: Reajuste | N14: =IF(L14="",MID(G14,FIND("de ",G14)+3,10),MID(L14,FIND("de ",L14)+3,10)) -> 28/04/2026 | O14: =TODAY()-N14 -> 147
B15: Neoenergia BA (COELBA) | C15: 2.67604 | D15: 0.42776 | E15: 0.10142 | F15: 0.26248 | G15: RES. 3.443, de 15/04/2025 | H15: 2.75779 | I15: 0.44144 | J15: 0.1391 | K15: 0.25224 | L15: RES. 3.578, de 22/04/2026 | M15: Reajuste | N15: =IF(L15="",MID(G15,FIND("de ",G15)+3,10),MID(L15,FIND("de ",L15)+3,10)) -> 22/04/2026 | O15: =TODAY()-N15 -> 153
B16: Equatorial PI | C16: 2.29663 | D16: 0.46025 | E16: 0.14021 | F16: 0.2817 | G16: RES. 3.555, de 25/11/2025 | N16: =IF(L16="",MID(G16,FIND("de ",G16)+3,10),MID(L16,FIND("de ",L16)+3,10)) -> 25/11/2025 | O16: =TODAY()-N16 -> 301
B17: Energisa MS (EMS) | C17: 1.80993 | D17: 0.44621 | E17: 0.12998 | F17: 0.26963 | G17: RES. 3.441, de 08/04/2025 | H17: 1.89203 | I17: 0.48948 | J17: 0.17971 | K17: 0.30533 | L17: RES. 3.582, de 22/04/2026 | M17: Reajuste | N17: =IF(L17="",MID(G17,FIND("de ",G17)+3,10),MID(L17,FIND("de ",L17)+3,10)) -> 22/04/2026 | O17: =TODAY()-N17 -> 153
B18: CEMIG | C18: 1.80905 | D18: 0.47591 | E18: 0.15323 | F18: 0.29677 | G18: RES. 3.459, de 20/05/2025 | H18: 1.91296 | I18: 0.47422 | J18: 0.18579 | K18: 0.29498 | L18: RES. 3.589, de 26/05/2026 | M18: Reajuste | N18: =IF(L18="",MID(G18,FIND("de ",G18)+3,10),MID(L18,FIND("de ",L18)+3,10)) -> 26/05/2026 | O18: =TODAY()-N18 -> 119
B19: Equatorial AL | C19: 1.84193 | D19: 0.38757 | E19: 0.13851 | F19: 0.22405 | G19: RES. 3.450, de 29/04/2025 | H19: 1.87514 | I19: 0.38319 | J19: 0.17195 | K19: 0.19235 | L19: RES. 3.584, de 28/04/2026 | M19: Reajuste | N19: =IF(L19="",MID(G19,FIND("de ",G19)+3,10),MID(L19,FIND("de ",L19)+3,10)) -> 28/04/2026 | O19: =TODAY()-N19 -> 147
B20: COCEL | C20: 1.1046 | D20: 0.40263 | E20: 0.10789 | F20: 0.25411 | G20: RES. 3.476, de 24/06/2025 | H20: 1.39731 | I20: 0.44749 | J20: 0.12436 | K20: 0.27903 | L20: RES. 3.595, de 30/06/2026 | M20: Revisão | N20: =IF(L20="",MID(G20,FIND("de ",G20)+3,10),MID(L20,FIND("de ",L20)+3,10)) -> 30/06/2026 | O20: =TODAY()-N20 -> 84
B21: RGE Sul | C21: 1.69304 | D21: 0.45822 | E21: 0.11938 | F21: 0.28504 | G21: RES. 3.473, de 17/06/2025 | H21: 1.8349 | I21: 0.54657 | J21: 0.15777 | K21: 0.33873 | L21: RES. 3.590, de 16/06/2026 | M21: Reajuste | N21: =IF(L21="",MID(G21,FIND("de ",G21)+3,10),MID(L21,FIND("de ",L21)+3,10)) -> 16/06/2026 | O21: =TODAY()-N21 -> 98
B22: Equatorial GO | C22: 1.65616 | D22: 0.48489 | E22: 0.14961 | F22: 0.30387 | G22: RES. 3.544, de 21/10/2025 | N22: =IF(L22="",MID(G22,FIND("de ",G22)+3,10),MID(L22,FIND("de ",L22)+3,10)) -> 21/10/2025 | O22: =TODAY()-N22 -> 336
B23: Neoenergia RN (COSERN) | C23: 1.86781 | D23: 0.48578 | E23: 0.09156 | F23: 0.29476 | G23: RES. 3.442, de 15/04/2025 | H23: 2.00969 | I23: 0.48553 | J23: 0.11719 | K23: 0.28257 | L23: RES. 3.573, de 22/04/2026 | M23: Reajuste | N23: =IF(L23="",MID(G23,FIND("de ",G23)+3,10),MID(L23,FIND("de ",L23)+3,10)) -> 22/04/2026 | O23: =TODAY()-N23 -> 153
B24: CELESC | C24: 1.06941 | D24: 0.48363 | E24: 0.14435 | F24: 0.30123 | G24: RES. 3.511, de 19/08/2025 | H24: 1.18924 | I24: 0.52711 | J24: 0.17119 | K24: 0.32908 | L24: RES. 3.602, de 18/08/2026 | M24: Revisão | N24: =IF(L24="",MID(G24,FIND("de ",G24)+3,10),MID(L24,FIND("de ",L24)+3,10)) -> 18/08/2026 | O24: =TODAY()-N24 -> 35
B25: Roraima Energia (Boa Vista) | C25: 1.26649 | D25: 0.50138 | E25: 0.09841 | F25: 0.28832 | G25: RES. 3.434, de 21/01/2025 | H25: 1.60696 | I25: 0.52553 | J25: 0.15459 | K25: 0.32733 | L25: RES. 3.565, de 20/01/2026 | M25: Reajuste | N25: =IF(L25="",MID(G25,FIND("de ",G25)+3,10),MID(L25,FIND("de ",L25)+3,10)) -> 20/01/2026 | O25: =TODAY()-N25 -> 245
B26: Neoenergia Elektro (ELEKTRO) | C26: 1.92309 | D26: 0.48004 | E26: 0.13852 | F26: 0.29732 | G26: RES. 3.510, de 19/08/2025 | H26: 1.70728 | I26: 0.49666 | J26: 0.1719 | K26: 0.31068 | L26: RES. 3.605, de 24/08/2026 | M26: Reajuste | N26: =IF(L26="",MID(G26,FIND("de ",G26)+3,10),MID(L26,FIND("de ",L26)+3,10)) -> 24/08/2026 | O26: =TODAY()-N26 -> 29
B27: COPEL | C27: 1.21156 | D27: 0.41369 | E27: 0.12091 | F27: 0.25751 | G27: RES. 3.472, de 17/06/2025 | H27: 1.46339 | I27: 0.47555 | J27: 0.14659 | K27: 0.29575 | L27: RES. 3.592, de 23/06/2026 | M27: Revisão | N27: =IF(L27="",MID(G27,FIND("de ",G27)+3,10),MID(L27,FIND("de ",L27)+3,10)) -> 23/06/2026 | O27: =TODAY()-N27 -> 91
B28: Enel CE | C28: 1.1629 | D28: 0.37247 | E28: 0.08846 | F28: 0.2325 | G28: RES. 3.445, de 15/04/2025 | H28: 1.13477 | I28: 0.4092 | J28: 0.12386 | K28: 0.24531 | L28: RES. 3.574, de 22/04/2026 | M28: Reajuste | N28: =IF(L28="",MID(G28,FIND("de ",G28)+3,10),MID(L28,FIND("de ",L28)+3,10)) -> 22/04/2026 | O28: =TODAY()-N28 -> 153
B29: Energisa SE (ESE) | C29: 1.70294 | D29: 0.4265 | E29: 0.08493 | F29: 0.25765 | G29: RES. 3.444, de 15/04/2025 | H29: 1.71878 | I29: 0.46311 | J29: 0.12233 | K29: 0.26488 | L29: RES. 3.575, de 22/04/2026 | M29: Reajuste | N29: =IF(L29="",MID(G29,FIND("de ",G29)+3,10),MID(L29,FIND("de ",L29)+3,10)) -> 22/04/2026 | O29: =TODAY()-N29 -> 153
B30: CEEE Equatorial | C30: 1.66415 | D30: 0.50961 | E30: 0.15092 | F30: 0.32265 | G30: RES. 3.547, de 18/11/2025 | N30: =IF(L30="",MID(G30,FIND("de ",G30)+3,10),MID(L30,FIND("de ",L30)+3,10)) -> 18/11/2025 | O30: =TODAY()-N30 -> 308
B31: CPFL Paulista | C31: 1.29459 | D31: 0.44454 | E31: 0.11447 | F31: 0.27119 | G31: RES. 3.452, de 29/04/2025 | H31: 1.35157 | I31: 0.43188 | J31: 0.16416 | K31: 0.27282 | L31: RES. 3.579, de 22/04/2026 | M31: Reajuste | N31: =IF(L31="",MID(G31,FIND("de ",G31)+3,10),MID(L31,FIND("de ",L31)+3,10)) -> 22/04/2026 | O31: =TODAY()-N31 -> 153
B32: CPFL Piratininga | C32: 0.9439 | D32: 0.51345 | E32: 0.12899 | F32: 0.32277 | G32: RES. 3.543, de 21/10/2025 | N32: =IF(L32="",MID(G32,FIND("de ",G32)+3,10),MID(L32,FIND("de ",L32)+3,10)) -> 21/10/2025 | O32: =TODAY()-N32 -> 336
B33: EDP SP | C33: 1.32563 | D33: 0.48903 | E33: 0.14205 | F33: 0.30923 | G33: RES. 3.541, de 14/10/2025 | N33: =IF(L33="",MID(G33,FIND("de ",G33)+3,10),MID(L33,FIND("de ",L33)+3,10)) -> 14/10/2025 | O33: =TODAY()-N33 -> 343
B34: Neoenergia Brasília (CEB) | C34: 0.92752 | D34: 0.60225 | E34: 0.16742 | F34: 0.37795 | G34: RES. 3.542, de 22/10/2025 | N34: =IF(L34="",MID(G34,FIND("de ",G34)+3,10),MID(L34,FIND("de ",L34)+3,10)) -> 22/10/2025 | O34: =TODAY()-N34 -> 335
B35: Enel RJ | C35: 1.93406 | D35: 0.44591 | E35: 0.15 | F35: 0.27728 | G35: RES. 3.435, de 11/03/2025 | H35: 2.05729 | I35: 0.48969 | J35: 0.22356 | K35: 0.31086 | L35: RES. 3.570, de 10/03/2026 | M35: Reajuste | N35: =IF(L35="",MID(G35,FIND("de ",G35)+3,10),MID(L35,FIND("de ",L35)+3,10)) -> 10/03/2026 | O35: =TODAY()-N35 -> 196
B36: Enel SP (ELETROPAULO) | C36: 0.83707 | D36: 0.43913 | E36: 0.12505 | F36: 0.27354 | G36: RES. 3.477, de 01/07/2025 | H36: 0.92241 | I36: 0.48242 | J36: 0.15062 | K36: 0.30188 | L36: RES. 3.596, de 30/06/2026 | M36: Reajuste | N36: =IF(L36="",MID(G36,FIND("de ",G36)+3,10),MID(L36,FIND("de ",L36)+3,10)) -> 30/06/2026 | O36: =TODAY()-N36 -> 84
B37: Amazonas Energia | C37: 1.19971 | D37: 0.53038 | E37: 0.16666 | F37: 0.32926 | G37: RES. 3.454, de 20/05/2025 | H37: 1.25032 | I37: 0.55479 | J37: 0.22948 | K37: 0.29066 | L37: RES. 3.588, de 19/05/2026 | M37: Reajuste | N37: =IF(L37="",MID(G37,FIND("de ",G37)+3,10),MID(L37,FIND("de ",L37)+3,10)) -> 19/05/2026 | O37: =TODAY()-N37 -> 126
B38: Energisa Sul-Sudeste (ESS) | C38: 1.2433 | D38: 0.48664 | E38: 0.13277 | F38: 0.30118 | G38: RES. 3.480, de 01/07/2025 | H38: 1.38143 | I38: 0.49245 | J38: 0.14535 | K38: 0.3058 | L38: RES. 3.599, de 14/07/2026 | M38: Revisão | N38: =IF(L38="",MID(G38,FIND("de ",G38)+3,10),MID(L38,FIND("de ",L38)+3,10)) -> 14/07/2026 | O38: =TODAY()-N38 -> 70
B39: Equatorial AP (CEA) | C39: 2.2833 | D39: 0.35981 | E39: 0.19363 | F39: 0.19381 | G39: RES. 3.430, de 10/12/2024 | H39: 2.9972 | I39: 0.26573 | J39: 0.26738 | K39: 0.07571 | L39: RES. 3.572, de 07/04/2026 | M39: Reajuste | N39: =IF(L39="",MID(G39,FIND("de ",G39)+3,10),MID(L39,FIND("de ",L39)+3,10)) -> 07/04/2026 | O39: =TODAY()-N39 -> 168
B40: CHESP | C40: 1.65616 | D40: 0.4311 | E40: 0.14961 | F40: 0.27251 | G40: RES. 3.545, de 11/11/2025 | N40: =IF(L40="",MID(G40,FIND("de ",G40)+3,10),MID(L40,FIND("de ",L40)+3,10)) -> 11/11/2025 | O40: =TODAY()-N40 -> 315
B41: CPFL Santa Cruz | C41: 1.50234 | D41: 0.38313 | E41: 0.12574 | F41: 0.23231 | G41: RES. 3.460, de 20/05/2025 | H41: 1.82219 | I41: 0.37616 | J41: 0.15852 | K41: 0.23682 | L41: RES. 3.580, de 22/04/2026 | M41: Revisão | N41: =IF(L41="",MID(G41,FIND("de ",G41)+3,10),MID(L41,FIND("de ",L41)+3,10)) -> 22/04/2026 | O41: =TODAY()-N41 -> 153
...

Sheet Perfil dos Reajustes
B2: Concessionárias | C2: PONTA | E2: FORA PONTA
C3: TUSD | D3: TE | E3: TUSD | F3: TE
B4: Equatorial PA | C4: =IF(VLOOKUP($B4,'Tarifas e Resoluções'!$B$5:$M$44,7,FALSE)="","",(VLOOKUP($B4,'Tarifas e Resoluções'!$B$5:$M$44,7,FALSE)/VLOOKUP($B4,'Tarifas e Resoluções'!$B$5:$M$44,2,FALSE))-1) -> -0.024049594 | D4: =IF(VLOOKUP($B4,'Tarifas e Resoluções'!$B$5:$M$44,8,FALSE)="","",(VLOOKUP($B4,'Tarifas e Resoluções'!$B$5:$M$44,8,FALSE)/VLOOKUP($B4,'Tarifas e Resoluções'!$B$5:$M$44,3,FALSE))-1) -> 0.12023166 | E4: =IF(VLOOKUP($B4,'Tarifas e Resoluções'!$B$5:$M$44,9,FALSE)="","",(VLOOKUP($B4,'Tarifas e Resoluções'!$B$5:$M$44,9,FALSE)/VLOOKUP($B4,'Tarifas e Resoluções'!$B$5:$M$44,4,FALSE))-1) -> 0.26412485 | F4: =IF(VLOOKUP($B4,'Tarifas e Resoluções'!$B$5:$M$44,10,FALSE)="","",(VLOOKUP($B4,'Tarifas e Resoluções'!$B$5:$M$44,10,FALSE)/VLOOKUP($B4,'Tarifas e Resoluções'!$B$5:$M$44,5,FALSE))-1) -> 0.06079649
B5: Energisa TO (ETO) | C5: =IF(VLOOKUP($B5,'Tarifas e Resoluções'!$B$5:$M$44,7,FALSE)="","",(VLOOKUP($B5,'Tarifas e Resoluções'!$B$5:$M$44,7,FALSE)/VLOOKUP($B5,'Tarifas e Resoluções'!$B$5:$M$44,2,FALSE))-1) -> 0.024514109 | D5: =IF(VLOOKUP($B5,'Tarifas e Resoluções'!$B$5:$M$44,8,FALSE)="","",(VLOOKUP($B5,'Tarifas e Resoluções'!$B$5:$M$44,8,FALSE)/VLOOKUP($B5,'Tarifas e Resoluções'!$B$5:$M$44,3,FALSE))-1) -> 0.10328331 | E5: =IF(VLOOKUP($B5,'Tarifas e Resoluções'!$B$5:$M$44,9,FALSE)="","",(VLOOKUP($B5,'Tarifas e Resoluções'!$B$5:$M$44,9,FALSE)/VLOOKUP($B5,'Tarifas e Resoluções'!$B$5:$M$44,4,FALSE))-1) -> 0.2391284 | F5: =IF(VLOOKUP($B5,'Tarifas e Resoluções'!$B$5:$M$44,10,FALSE)="","",(VLOOKUP($B5,'Tarifas e Resoluções'!$B$5:$M$44,10,FALSE)/VLOOKUP($B5,'Tarifas e Resoluções'!$B$5:$M$44,5,FALSE))-1) -> 0.086332783
B6: Equatorial MA | C6: =IF(VLOOKUP($B6,'Tarifas e Resoluções'!$B$5:$M$44,7,FALSE)="","",(VLOOKUP($B6,'Tarifas e Resoluções'!$B$5:$M$44,7,FALSE)/VLOOKUP($B6,'Tarifas e Resoluções'!$B$5:$M$44,2,FALSE))-1) -> 0.0066331016 | D6: =IF(VLOOKUP($B6,'Tarifas e Resoluções'!$B$5:$M$44,8,FALSE)="","",(VLOOKUP($B6,'Tarifas e Resoluções'!$B$5:$M$44,8,FALSE)/VLOOKUP($B6,'Tarifas e Resoluções'!$B$5:$M$44,3,FALSE))-1) -> 0.096055167 | E6: =IF(VLOOKUP($B6,'Tarifas e Resoluções'!$B$5:$M$44,9,FALSE)="","",(VLOOKUP($B6,'Tarifas e Resoluções'!$B$5:$M$44,9,FALSE)/VLOOKUP($B6,'Tarifas e Resoluções'!$B$5:$M$44,4,FALSE))-1) -> 0.33560052 | F6: =IF(VLOOKUP($B6,'Tarifas e Resoluções'!$B$5:$M$44,10,FALSE)="","",(VLOOKUP($B6,'Tarifas e Resoluções'!$B$5:$M$44,10,FALSE)/VLOOKUP($B6,'Tarifas e Resoluções'!$B$5:$M$44,5,FALSE))-1) -> 0.035639256
B7: Energisa AC (EAC) | C7: =IF(VLOOKUP($B7,'Tarifas e Resoluções'!$B$5:$M$44,7,FALSE)="","",(VLOOKUP($B7,'Tarifas e Resoluções'!$B$5:$M$44,7,FALSE)/VLOOKUP($B7,'Tarifas e Resoluções'!$B$5:$M$44,2,FALSE))-1) | D7: =IF(VLOOKUP($B7,'Tarifas e Resoluções'!$B$5:$M$44,8,FALSE)="","",(VLOOKUP($B7,'Tarifas e Resoluções'!$B$5:$M$44,8,FALSE)/VLOOKUP($B7,'Tarifas e Resoluções'!$B$5:$M$44,3,FALSE))-1) | E7: =IF(VLOOKUP($B7,'Tarifas e Resoluções'!$B$5:$M$44,9,FALSE)="","",(VLOOKUP($B7,'Tarifas e Resoluções'!$B$5:$M$44,9,FALSE)/VLOOKUP($B7,'Tarifas e Resoluções'!$B$5:$M$44,4,FALSE))-1) | F7: =IF(VLOOKUP($B7,'Tarifas e Resoluções'!$B$5:$M$44,10,FALSE)="","",(VLOOKUP($B7,'Tarifas e Resoluções'!$B$5:$M$44,10,FALSE)/VLOOKUP($B7,'Tarifas e Resoluções'!$B$5:$M$44,5,FALSE))-1)
B8: Energisa RO (ERO) | C8: =IF(VLOOKUP($B8,'Tarifas e Resoluções'!$B$5:$M$44,7,FALSE)="","",(VLOOKUP($B8,'Tarifas e Resoluções'!$B$5:$M$44,7,FALSE)/VLOOKUP($B8,'Tarifas e Resoluções'!$B$5:$M$44,2,FALSE))-1) | D8: =IF(VLOOKUP($B8,'Tarifas e Resoluções'!$B$5:$M$44,8,FALSE)="","",(VLOOKUP($B8,'Tarifas e Resoluções'!$B$5:$M$44,8,FALSE)/VLOOKUP($B8,'Tarifas e Resoluções'!$B$5:$M$44,3,FALSE))-1) | E8: =IF(VLOOKUP($B8,'Tarifas e Resoluções'!$B$5:$M$44,9,FALSE)="","",(VLOOKUP($B8,'Tarifas e Resoluções'!$B$5:$M$44,9,FALSE)/VLOOKUP($B8,'Tarifas e Resoluções'!$B$5:$M$44,4,FALSE))-1) | F8: =IF(VLOOKUP($B8,'Tarifas e Resoluções'!$B$5:$M$44,10,FALSE)="","",(VLOOKUP($B8,'Tarifas e Resoluções'!$B$5:$M$44,10,FALSE)/VLOOKUP($B8,'Tarifas e Resoluções'!$B$5:$M$44,5,FALSE))-1)
B9: LIGHT (LIGHT SESA) | C9: =IF(VLOOKUP($B9,'Tarifas e Resoluções'!$B$5:$M$44,7,FALSE)="","",(VLOOKUP($B9,'Tarifas e Resoluções'!$B$5:$M$44,7,FALSE)/VLOOKUP($B9,'Tarifas e Resoluções'!$B$5:$M$44,2,FALSE))-1) -> 0.047657217 | D9: =IF(VLOOKUP($B9,'Tarifas e Resoluções'!$B$5:$M$44,8,FALSE)="","",(VLOOKUP($B9,'Tarifas e Resoluções'!$B$5:$M$44,8,FALSE)/VLOOKUP($B9,'Tarifas e Resoluções'!$B$5:$M$44,3,FALSE))-1) -> -0.051129092 | E9: =IF(VLOOKUP($B9,'Tarifas e Resoluções'!$B$5:$M$44,9,FALSE)="","",(VLOOKUP($B9,'Tarifas e Resoluções'!$B$5:$M$44,9,FALSE)/VLOOKUP($B9,'Tarifas e Resoluções'!$B$5:$M$44,4,FALSE))-1) -> 0.33133127 | F9: =IF(VLOOKUP($B9,'Tarifas e Resoluções'!$B$5:$M$44,10,FALSE)="","",(VLOOKUP($B9,'Tarifas e Resoluções'!$B$5:$M$44,10,FALSE)/VLOOKUP($B9,'Tarifas e Resoluções'!$B$5:$M$44,5,FALSE))-1) -> -0.030540834
B10: Energisa MT (EMT) | C10: =IF(VLOOKUP($B10,'Tarifas e Resoluções'!$B$5:$M$44,7,FALSE)="","",(VLOOKUP($B10,'Tarifas e Resoluções'!$B$5:$M$44,7,FALSE)/VLOOKUP($B10,'Tarifas e Resoluções'!$B$5:$M$44,2,FALSE))-1) -> 0.055267935 | D10: =IF(VLOOKUP($B10,'Tarifas e Resoluções'!$B$5:$M$44,8,FALSE)="","",(VLOOKUP($B10,'Tarifas e Resoluções'!$B$5:$M$44,8,FALSE)/VLOOKUP($B10,'Tarifas e Resoluções'!$B$5:$M$44,3,FALSE))-1) -> 0.019889088 | E10: =IF(VLOOKUP($B10,'Tarifas e Resoluções'!$B$5:$M$44,9,FALSE)="","",(VLOOKUP($B10,'Tarifas e Resoluções'!$B$5:$M$44,9,FALSE)/VLOOKUP($B10,'Tarifas e Resoluções'!$B$5:$M$44,4,FALSE))-1) -> 0.26623426 | F10: =IF(VLOOKUP($B10,'Tarifas e Resoluções'!$B$5:$M$44,10,FALSE)="","",(VLOOKUP($B10,'Tarifas e Resoluções'!$B$5:$M$44,10,FALSE)/VLOOKUP($B10,'Tarifas e Resoluções'!$B$5:$M$44,5,FALSE))-1) -> -0.00056215305
B11: Energisa PB (EPB) | C11: =IF(VLOOKUP($B11,'Tarifas e Resoluções'!$B$5:$M$44,7,FALSE)="","",(VLOOKUP($B11,'Tarifas e Resoluções'!$B$5:$M$44,7,FALSE)/VLOOKUP($B11,'Tarifas e Resoluções'!$B$5:$M$44,2,FALSE))-1) -> 0.0065234015 | D11: =IF(VLOOKUP($B11,'Tarifas e Resoluções'!$B$5:$M$44,8,FALSE)="","",(VLOOKUP($B11,'Tarifas e Resoluções'!$B$5:$M$44,8,FALSE)/VLOOKUP($B11,'Tarifas e Resoluções'!$B$5:$M$44,3,FALSE))-1) -> 0.057598735 | E11: =IF(VLOOKUP($B11,'Tarifas e Resoluções'!$B$5:$M$44,9,FALSE)="","",(VLOOKUP($B11,'Tarifas e Resoluções'!$B$5:$M$44,9,FALSE)/VLOOKUP($B11,'Tarifas e Resoluções'!$B$5:$M$44,4,FALSE))-1) -> 0.28433662 | F11: =IF(VLOOKUP($B11,'Tarifas e Resoluções'!$B$5:$M$44,10,FALSE)="","",(VLOOKUP($B11,'Tarifas e Resoluções'!$B$5:$M$44,10,FALSE)/VLOOKUP($B11,'Tarifas e Resoluções'!$B$5:$M$44,5,FALSE))-1) -> 0.019401745
B12: SULGIPE | C12: =IF(VLOOKUP($B12,'Tarifas e Resoluções'!$B$5:$M$44,7,FALSE)="","",(VLOOKUP($B12,'Tarifas e Resoluções'!$B$5:$M$44,7,FALSE)/VLOOKUP($B12,'Tarifas e Resoluções'!$B$5:$M$44,2,FALSE))-1) -> 0.0093015608 | D12: =IF(VLOOKUP($B12,'Tarifas e Resoluções'!$B$5:$M$44,8,FALSE)="","",(VLOOKUP($B12,'Tarifas e Resoluções'!$B$5:$M$44,8,FALSE)/VLOOKUP($B12,'Tarifas e Resoluções'!$B$5:$M$44,3,FALSE))-1) -> 0.039108841 | E12: =IF(VLOOKUP($B12,'Tarifas e Resoluções'!$B$5:$M$44,9,FALSE)="","",(VLOOKUP($B12,'Tarifas e Resoluções'!$B$5:$M$44,9,FALSE)/VLOOKUP($B12,'Tarifas e Resoluções'!$B$5:$M$44,4,FALSE))-1) -> 0.44036265 | F12: =IF(VLOOKUP($B12,'Tarifas e Resoluções'!$B$5:$M$44,10,FALSE)="","",(VLOOKUP($B12,'Tarifas e Resoluções'!$B$5:$M$44,10,FALSE)/VLOOKUP($B12,'Tarifas e Resoluções'!$B$5:$M$44,5,FALSE))-1) -> 0.022803549
B13: Neoenergia PE | C13: =IF(VLOOKUP($B13,'Tarifas e Resoluções'!$B$5:$M$44,7,FALSE)="","",(VLOOKUP($B13,'Tarifas e Resoluções'!$B$5:$M$44,7,FALSE)/VLOOKUP($B13,'Tarifas e Resoluções'!$B$5:$M$44,2,FALSE))-1) -> -0.093498124 | D13: =IF(VLOOKUP($B13,'Tarifas e Resoluções'!$B$5:$M$44,8,FALSE)="","",(VLOOKUP($B13,'Tarifas e Resoluções'!$B$5:$M$44,8,FALSE)/VLOOKUP($B13,'Tarifas e Resoluções'!$B$5:$M$44,3,FALSE))-1) -> 0.0022669506 | E13: =IF(VLOOKUP($B13,'Tarifas e Resoluções'!$B$5:$M$44,9,FALSE)="","",(VLOOKUP($B13,'Tarifas e Resoluções'!$B$5:$M$44,9,FALSE)/VLOOKUP($B13,'Tarifas e Resoluções'!$B$5:$M$44,4,FALSE))-1) -> 0.30534432 | F13: =IF(VLOOKUP($B13,'Tarifas e Resoluções'!$B$5:$M$44,10,FALSE)="","",(VLOOKUP($B13,'Tarifas e Resoluções'!$B$5:$M$44,10,FALSE)/VLOOKUP($B13,'Tarifas e Resoluções'!$B$5:$M$44,5,FALSE))-1) -> -0.040698985
B14: Neoenergia BA (COELBA) | C14: =IF(VLOOKUP($B14,'Tarifas e Resoluções'!$B$5:$M$44,7,FALSE)="","",(VLOOKUP($B14,'Tarifas e Resoluções'!$B$5:$M$44,7,FALSE)/VLOOKUP($B14,'Tarifas e Resoluções'!$B$5:$M$44,2,FALSE))-1) -> 0.030548871 | D14: =IF(VLOOKUP($B14,'Tarifas e Resoluções'!$B$5:$M$44,8,FALSE)="","",(VLOOKUP($B14,'Tarifas e Resoluções'!$B$5:$M$44,8,FALSE)/VLOOKUP($B14,'Tarifas e Resoluções'!$B$5:$M$44,3,FALSE))-1) -> 0.03198055 | E14: =IF(VLOOKUP($B14,'Tarifas e Resoluções'!$B$5:$M$44,9,FALSE)="","",(VLOOKUP($B14,'Tarifas e Resoluções'!$B$5:$M$44,9,FALSE)/VLOOKUP($B14,'Tarifas e Resoluções'!$B$5:$M$44,4,FALSE))-1) -> 0.37152435 | F14: =IF(VLOOKUP($B14,'Tarifas e Resoluções'!$B$5:$M$44,10,FALSE)="","",(VLOOKUP($B14,'Tarifas e Resoluções'!$B$5:$M$44,10,FALSE)/VLOOKUP($B14,'Tarifas e Resoluções'!$B$5:$M$44,5,FALSE))-1) -> -0.039012496
B15: Equatorial PI | C15: =IF(VLOOKUP($B15,'Tarifas e Resoluções'!$B$5:$M$44,7,FALSE)="","",(VLOOKUP($B15,'Tarifas e Resoluções'!$B$5:$M$44,7,FALSE)/VLOOKUP($B15,'Tarifas e Resoluções'!$B$5:$M$44,2,FALSE))-1) | D15: =IF(VLOOKUP($B15,'Tarifas e Resoluções'!$B$5:$M$44,8,FALSE)="","",(VLOOKUP($B15,'Tarifas e Resoluções'!$B$5:$M$44,8,FALSE)/VLOOKUP($B15,'Tarifas e Resoluções'!$B$5:$M$44,3,FALSE))-1) | E15: =IF(VLOOKUP($B15,'Tarifas e Resoluções'!$B$5:$M$44,9,FALSE)="","",(VLOOKUP($B15,'Tarifas e Resoluções'!$B$5:$M$44,9,FALSE)/VLOOKUP($B15,'Tarifas e Resoluções'!$B$5:$M$44,4,FALSE))-1) | F15: =IF(VLOOKUP($B15,'Tarifas e Resoluções'!$B$5:$M$44,10,FALSE)="","",(VLOOKUP($B15,'Tarifas e Resoluções'!$B$5:$M$44,10,FALSE)/VLOOKUP($B15,'Tarifas e Resoluções'!$B$5:$M$44,5,FALSE))-1)
... B43: FORCEL (Pacto Energia PR) | C43: =IF(VLOOKUP($B43,'Tarifas e Resoluções'!$B$5:$M$44,7,FALSE)="","",(VLOOKUP($B43,'Tarifas e Resoluções'!$B$5:$M$44,7,FALSE)/VLOOKUP($B43,'Tarifas e Resoluções'!$B$5:$M$44,2,FALSE))-1) | D43: =IF(VLOOKUP($B43,'Tarifas e Resoluções'!$B$5:$M$44,8,FALSE)="","",(VLOOKUP($B43,'Tarifas e Resoluções'!$B$5:$M$44,8,FALSE)/VLOOKUP($B43,'Tarifas e Resoluções'!$B$5:$M$44,3,FALSE))-1) | E43: =IF(VLOOKUP($B43,'Tarifas e Resoluções'!$B$5:$M$44,9,FALSE)="","",(VLOOKUP($B43,'Tarifas e Resoluções'!$B$5:$M$44,9,FALSE)/VLOOKUP($B43,'Tarifas e Resoluções'!$B$5:$M$44,4,FALSE))-1) | F43: =IF(VLOOKUP($B43,'Tarifas e Resoluções'!$B$5:$M$44,10,FALSE)="","",(VLOOKUP($B43,'Tarifas e Resoluções'!$B$5:$M$44,10,FALSE)/VLOOKUP($B43,'Tarifas e Resoluções'!$B$5:$M$44,5,FALSE))-1)

Sheet Tarifas Ponta Cativo
B2: Concessionárias | C2: Estado | D2: ICMS | E2: PIS/COFINS | F2: ANTERIOR | H2: ATUAL | J2: Reajuste | L2: RANKING TUSD + TE Ponta - Mercado Cativo
F3: TUSD P + TE P | H3: TUSD P + TE P
F4: S/ Imp | G4: C/ Imp | H4: S/ Imp | I4: C/ Imp | L4: Concessionária | M4: Estado | N4: Tarifa Ponta
B5: ='Tarifas e Resoluções'!B5 -> Equatorial PA | C5: PA | D5: =VLOOKUP(C5,Rascunho!$B$3:$C$29,2,FALSE) -> 0.19 | E5: 0.05 | F5: =VLOOKUP($B5,'Tarifas e Resoluções'!$B$5:$M$44,2,FALSE)+VLOOKUP($B5,'Tarifas e Resoluções'!$B$5:$M$44,3,FALSE) -> 3.02115 | G5: =F5/(1-E5)/(1-D5) -> 3.9261209 | H5: =IF(VLOOKUP($B5,'Tarifas e Resoluções'!$B$5:$M$44,7,FALSE)="","",VLOOKUP($B5,'Tarifas e Resoluções'!$B$5:$M$44,7,FALSE)+VLOOKUP($B5,'Tarifas e Resoluções'!$B$5:$M$44,8,FALSE)) -> 3.01177 | I5: =IFERROR(H5/(1-E5)/(1-D5),"") -> 3.9139311 | J5: =IFERROR(I5/G5-1,"") -> -0.003104778 | L5: =VLOOKUP(N5,Rascunho!$E$4:$G$43,2,FALSE) -> Equatorial AP (CEA) | M5: =VLOOKUP(N5,Rascunho!$E$4:$G$43,3,FALSE) -> AP | N5: =LARGE(Rascunho!$E$4:$E$43,1) -> 4.1886136
B6: ='Tarifas e Resoluções'!B6 -> Energisa TO (ETO) | C6: TO | D6: =VLOOKUP(C6,Rascunho!$B$3:$C$29,2,FALSE) -> 0.2 | E6: =E5 -> 0.05 | F6: =VLOOKUP($B6,'Tarifas e Resoluções'!$B$5:$M$44,2,FALSE)+VLOOKUP($B6,'Tarifas e Resoluções'!$B$5:$M$44,3,FALSE) -> 2.48116 | G6: =F6/(1-E6)/(1-D6) -> 3.2646842 | H6: =IF(VLOOKUP($B6,'Tarifas e Resoluções'!$B$5:$M$44,7,FALSE)="","",VLOOKUP($B6,'Tarifas e Resoluções'!$B$5:$M$44,7,FALSE)+VLOOKUP($B6,'Tarifas e Resoluções'!$B$5:$M$44,8,FALSE)) -> 2.57689 | I6: =IFERROR(H6/(1-E6)/(1-D6),"") -> 3.3906447 | J6: =IFERROR(I6/G6-1,"") -> 0.03858276 | L6: =VLOOKUP(N6,Rascunho!$E$4:$G$43,2,FALSE) -> Energisa AC (EAC) | M6: =VLOOKUP(N6,Rascunho!$E$4:$G$43,3,FALSE) -> AC | N6: =LARGE(Rascunho!$E$4:$E$43,2) -> 3.9532034
B7: ='Tarifas e Resoluções'!B7 -> Equatorial MA | C7: MA | D7: =VLOOKUP(C7,Rascunho!$B$3:$C$29,2,FALSE) -> 0.22 | E7: =E6 -> 0.05 | F7: =VLOOKUP($B7,'Tarifas e Resoluções'!$B$5:$M$44,2,FALSE)+VLOOKUP($B7,'Tarifas e Resoluções'!$B$5:$M$44,3,FALSE) -> 2.80816 | G7: =F7/(1-E7)/(1-D7) -> 3.7896896 | H7: =IF(VLOOKUP($B7,'Tarifas e Resoluções'!$B$5:$M$44,7,FALSE)="","",VLOOKUP($B7,'Tarifas e Resoluções'!$B$5:$M$44,7,FALSE)+VLOOKUP($B7,'Tarifas e Resoluções'!$B$5:$M$44,8,FALSE)) -> 2.8653 | I7: =IFERROR(H7/(1-E7)/(1-D7),"") -> 3.8668016 | J7: =IFERROR(I7/G7-1,"") -> 0.020347843 | L7: =VLOOKUP(N7,Rascunho!$E$4:$G$43,2,FALSE) -> Equatorial PA | M7: =VLOOKUP(N7,Rascunho!$E$4:$G$43,3,FALSE) -> PA | N7: =LARGE(Rascunho!$E$4:$E$43,3) -> 3.9139311
B8: ='Tarifas e Resoluções'!B8 -> Energisa AC (EAC) | C8: AC | D8: =VLOOKUP(C8,Rascunho!$B$3:$C$29,2,FALSE) -> 0.19 | E8: =E7 -> 0.05 | F8: =VLOOKUP($B8,'Tarifas e Resoluções'!$B$5:$M$44,2,FALSE)+VLOOKUP($B8,'Tarifas e Resoluções'!$B$5:$M$44,3,FALSE) -> 3.04199 | G8: =F8/(1-E8)/(1-D8) -> 3.9532034 | H8: =IF(VLOOKUP($B8,'Tarifas e Resoluções'!$B$5:$M$44,7,FALSE)="","",VLOOKUP($B8,'Tarifas e Resoluções'!$B$5:$M$44,7,FALSE)+VLOOKUP($B8,'Tarifas e Resoluções'!$B$5:$M$44,8,FALSE)) | I8: =IFERROR(H8/(1-E8)/(1-D8),"") | J8: =IFERROR(I8/G8-1,"") | L8: =VLOOKUP(N8,Rascunho!$E$4:$G$43,2,FALSE) -> Neoenergia BA (COELBA) | M8: =VLOOKUP(N8,Rascunho!$E$4:$G$43,3,FALSE) -> BA | N8: =LARGE(Rascunho!$E$4:$E$43,4) -> 3.8685934
B9: ='Tarifas e Resoluções'!B9 -> Energisa RO (ERO) | C9: RO | D9: =VLOOKUP(C9,Rascunho!$B$3:$C$29,2,FALSE) -> 0.195 | E9: =E8 -> 0.05 | F9: =VLOOKUP($B9,'Tarifas e Resoluções'!$B$5:$M$44,2,FALSE)+VLOOKUP($B9,'Tarifas e Resoluções'!$B$5:$M$44,3,FALSE) -> 2.9157 | G9: =F9/(1-E9)/(1-D9) -> 3.8126185 | H9: =IF(VLOOKUP($B9,'Tarifas e Resoluções'!$B$5:$M$44,7,FALSE)="","",VLOOKUP($B9,'Tarifas e Resoluções'!$B$5:$M$44,7,FALSE)+VLOOKUP($B9,'Tarifas e Resoluções'!$B$5:$M$44,8,FALSE)) | I9: =IFERROR(H9/(1-E9)/(1-D9),"") | J9: =IFERROR(I9/G9-1,"") | L9: =VLOOKUP(N9,Rascunho!$E$4:$G$43,2,FALSE) -> Equatorial MA | M9: =VLOOKUP(N9,Rascunho!$E$4:$G$43,3,FALSE) -> MA | N9: =LARGE(Rascunho!$E$4:$E$43,5) -> 3.8668016
B10: ='Tarifas e Resoluções'!B10 -> LIGHT (LIGHT SESA) | C10: RJ | D10: =VLOOKUP(C10,Rascunho!$B$3:$C$29,2,FALSE) -> 0.22 | E10: =E9 -> 0.05 | F10: =VLOOKUP($B10,'Tarifas e Resoluções'!$B$5:$M$44,2,FALSE)+VLOOKUP($B10,'Tarifas e Resoluções'!$B$5:$M$44,3,FALSE) -> 1.5838 | G10: =F10/(1-E10)/(1-D10) -> 2.1373819 | H10: =IF(VLOOKUP($B10,'Tarifas e Resoluções'!$B$5:$M$44,7,FALSE)="","",VLOOKUP($B10,'Tarifas e Resoluções'!$B$5:$M$44,7,FALSE)+VLOOKUP($B10,'Tarifas e Resoluções'!$B$5:$M$44,8,FALSE)) -> 1.61374 | I10: =IFERROR(H10/(1-E10)/(1-D10),"") -> 2.1777868 | J10: =IFERROR(I10/G10-1,"") -> 0.018903902 | L10: =VLOOKUP(N10,Rascunho!$E$4:$G$43,2,FALSE) -> Energisa RO (ERO) | M10: =VLOOKUP(N10,Rascunho!$E$4:$G$43,3,FALSE) -> RO | N10: =LARGE(Rascunho!$E$4:$E$43,6) -> 3.8126185
B11: ='Tarifas e Resoluções'!B11 -> Energisa MT (EMT) | C11: MT | D11: =VLOOKUP(C11,Rascunho!$B$3:$C$29,2,FALSE) -> 0.17 | E11: =E10 -> 0.05 | F11: =VLOOKUP($B11,'Tarifas e Resoluções'!$B$5:$M$44,2,FALSE)+VLOOKUP($B11,'Tarifas e Resoluções'!$B$5:$M$44,3,FALSE) -> 2.19295 | G11: =F11/(1-E11)/(1-D11) -> 2.7811668 | H11: =IF(VLOOKUP($B11,'Tarifas e Resoluções'!$B$5:$M$44,7,FALSE)="","",VLOOKUP($B11,'Tarifas e Resoluções'!$B$5:$M$44,7,FALSE)+VLOOKUP($B11,'Tarifas e Resoluções'!$B$5:$M$44,8,FALSE)) -> 2.29718 | I11: =IFERROR(H11/(1-E11)/(1-D11),"") -> 2.9133545 | J11: =IFERROR(I11/G11-1,"") -> 0.047529583 | L11: =VLOOKUP(N11,Rascunho!$E$4:$G$43,2,FALSE) -> Equatorial PI | M11: =VLOOKUP(N11,Rascunho!$E$4:$G$43,3,FALSE) -> PI | N11: =LARGE(Rascunho!$E$4:$E$43,7) -> 3.744489
B12: ='Tarifas e Resoluções'!B12 -> Energisa PB (EPB) | C12: PB | D12: =VLOOKUP(C12,Rascunho!$B$3:$C$29,2,FALSE) -> 0.2 | E12: =E11 -> 0.05 | F12: =VLOOKUP($B12,'Tarifas e Resoluções'!$B$5:$M$44,2,FALSE)+VLOOKUP($B12,'Tarifas e Resoluções'!$B$5:$M$44,3,FALSE) -> 1.68641 | G12: =F12/(1-E12)/(1-D12) -> 2.2189605 | H12: =IF(VLOOKUP($B12,'Tarifas e Resoluções'!$B$5:$M$44,7,FALSE)="","",VLOOKUP($B12,'Tarifas e Resoluções'!$B$5:$M$44,7,FALSE)+VLOOKUP($B12,'Tarifas e Resoluções'!$B$5:$M$44,8,FALSE)) -> 1.71809 | I12: =IFERROR(H12/(1-E12)/(1-D12),"") -> 2.2606447 | J12: =IFERROR(I12/G12-1,"") -> 0.018785467 | L12: =VLOOKUP(N12,Rascunho!$E$4:$G$43,2,FALSE) -> Enel RJ | M12: =VLOOKUP(N12,Rascunho!$E$4:$G$43,3,FALSE) -> RJ | N12: =LARGE(Rascunho!$E$4:$E$43,8) -> 3.43722
B13: ='Tarifas e Resoluções'!B13 -> SULGIPE | C13: SE | D13: =VLOOKUP(C13,Rascunho!$B$3:$C$29,2,FALSE) -> 0.2 | E13: =E12 -> 0.05 | F13: =VLOOKUP($B13,'Tarifas e Resoluções'!$B$5:$M$44,2,FALSE)+VLOOKUP($B13,'Tarifas e Resoluções'!$B$5:$M$44,3,FALSE) -> 2.05529 | G13: =F13/(1-E13)/(1-D13) -> 2.7043289 | H13: =IF(VLOOKUP($B13,'Tarifas e Resoluções'!$B$5:$M$44,7,FALSE)="","",VLOOKUP($B13,'Tarifas e Resoluções'!$B$5:$M$44,7,FALSE)+VLOOKUP($B13,'Tarifas e Resoluções'!$B$5:$M$44,8,FALSE)) -> 2.08491 | I13: =IFERROR(H13/(1-E13)/(1-D13),"") -> 2.7433026 | J13: =IFERROR(I13/G13-1,"") -> 0.014411592 | L13: =VLOOKUP(N13,Rascunho!$E$4:$G$43,2,FALSE) -> Energisa TO (ETO) | M13: =VLOOKUP(N13,Rascunho!$E$4:$G$43,3,FALSE) -> TO | N13: =LARGE(Rascunho!$E$4:$E$43,9) -> 3.3906447
B14: ='Tarifas e Resoluções'!B14 -> Neoenergia PE | C14: PE | D14: =VLOOKUP(C14,Rascunho!$B$3:$C$29,2,FALSE) -> 0.205 | E14: =E13 -> 0.05 | F14: =VLOOKUP($B14,'Tarifas e Resoluções'!$B$5:$M$44,2,FALSE)+VLOOKUP($B14,'Tarifas e Resoluções'!$B$5:$M$44,3,FALSE) -> 1.68112 | G14: =F14/(1-E14)/(1-D14) -> 2.2259119 | H14: =IF(VLOOKUP($B14,'Tarifas e Resoluções'!$B$5:$M$44,7,FALSE)="","",VLOOKUP($B14,'Tarifas e Resoluções'!$B$5:$M$44,7,FALSE)+VLOOKUP($B14,'Tarifas e Resoluções'!$B$5:$M$44,8,FALSE)) -> 1.56576 | I14: =IFERROR(H14/(1-E14)/(1-D14),"") -> 2.0731678 | J14: =IFERROR(I14/G14-1,"") -> -0.068620919 | L14: =VLOOKUP(N14,Rascunho!$E$4:$G$43,2,FALSE) -> Energisa Minas Rio (EMR) | M14: =VLOOKUP(N14,Rascunho!$E$4:$G$43,3,FALSE) -> MG | N14: =LARGE(Rascunho!$E$4:$E$43,10) -> 3.2073299
B15: ='Tarifas e Resoluções'!B15 -> Neoenergia BA (COELBA) | C15: BA | D15: =VLOOKUP(C15,Rascunho!$B$3:$C$29,2,FALSE) -> 0.1295 | E15: =E14 -> 0.05 | F15: =VLOOKUP($B15,'Tarifas e Resoluções'!$B$5:$M$44,2,FALSE)+VLOOKUP($B15,'Tarifas e Resoluções'!$B$5:$M$44,3,FALSE) -> 3.1038 | G15: =F15/(1-E15)/(1-D15) -> 3.7531969 | H15: =IF(VLOOKUP($B15,'Tarifas e Resoluções'!$B$5:$M$44,7,FALSE)="","",VLOOKUP($B15,'Tarifas e Resoluções'!$B$5:$M$44,7,FALSE)+VLOOKUP($B15,'Tarifas e Resoluções'!$B$5:$M$44,8,FALSE)) -> 3.19923 | I15: =IFERROR(H15/(1-E15)/(1-D15),"") -> 3.8685934 | J15: =IFERROR(I15/G15-1,"") -> 0.030746182 | L15: =VLOOKUP(N15,Rascunho!$E$4:$G$43,2,FALSE) -> Neoenergia RN (COSERN) | M15: =VLOOKUP(N15,Rascunho!$E$4:$G$43,3,FALSE) -> RN | N15: =LARGE(Rascunho!$E$4:$E$43,11) -> 3.2031065
B16: ='Tarifas e Resoluções'!B16 -> Equatorial PI | C16: PI | D16: =VLOOKUP(C16,Rascunho!$B$3:$C$29,2,FALSE) -> 0.225 | E16: =E15 -> 0.05 | F16: =VLOOKUP($B16,'Tarifas e Resoluções'!$B$5:$M$44,2,FALSE)+VLOOKUP($B16,'Tarifas e Resoluções'!$B$5:$M$44,3,FALSE) -> 2.75688 | G16: =F16/(1-E16)/(1-D16) -> 3.744489 | H16: =IF(VLOOKUP($B16,'Tarifas e Resoluções'!$B$5:$M$44,7,FALSE)="","",VLOOKUP($B16,'Tarifas e Resoluções'!$B$5:$M$44,7,FALSE)+VLOOKUP($B16,'Tarifas e Resoluções'!$B$5:$M$44,8,FALSE)) | I16: =IFERROR(H16/(1-E16)/(1-D16),"") | J16: =IFERROR(I16/G16-1,"") | L16: =VLOOKUP(N16,Rascunho!$E$4:$G$43,2,FALSE) -> CEMIG | M16: =VLOOKUP(N16,Rascunho!$E$4:$G$43,3,FALSE) -> MG | N16: =LARGE(Rascunho!$E$4:$E$43,12) -> 3.0644159
B17: ='Tarifas e Resoluções'!B17 -> Energisa MS (EMS) | C17: MS | D17: =VLOOKUP(C17,Rascunho!$B$3:$C$29,2,FALSE) -> 0.17 | E17: =E16 -> 0.05 | F17: =VLOOKUP($B17,'Tarifas e Resoluções'!$B$5:$M$44,2,FALSE)+VLOOKUP($B17,'Tarifas e Resoluções'!$B$5:$M$44,3,FALSE) -> 2.25614 | G17: =F17/(1-E17)/(1-D17) -> 2.8613063 | H17: =IF(VLOOKUP($B17,'Tarifas e Resoluções'!$B$5:$M$44,7,FALSE)="","",VLOOKUP($B17,'Tarifas e Resoluções'!$B$5:$M$44,7,FALSE)+VLOOKUP($B17,'Tarifas e Resoluções'!$B$5:$M$44,8,FALSE)) -> 2.38151 | I17: =IFERROR(H17/(1-E17)/(1-D17),"") -> 3.0203044 | J17: =IFERROR(I17/G17-1,"") -> 0.05556836 | L17: =VLOOKUP(N17,Rascunho!$E$4:$G$43,2,FALSE) -> Energisa MS (EMS) | M17: =VLOOKUP(N17,Rascunho!$E$4:$G$43,3,FALSE) -> MS | N17: =LARGE(Rascunho!$E$4:$E$43,13) -> 3.0203044
B18: ='Tarifas e Resoluções'!B18 -> CEMIG | C18: MG | D18: =VLOOKUP(C18,Rascunho!$B$3:$C$29,2,FALSE) -> 0.18 | E18: =E17 -> 0.05 | F18: =VLOOKUP($B18,'Tarifas e Resoluções'!$B$5:$M$44,2,FALSE)+VLOOKUP($B18,'Tarifas e Resoluções'!$B$5:$M$44,3,FALSE) -> 2.28496 | G18: =F18/(1-E18)/(1-D18) -> 2.9331964 | H18: =IF(VLOOKUP($B18,'Tarifas e Resoluções'!$B$5:$M$44,7,FALSE)="","",VLOOKUP($B18,'Tarifas e Resoluções'!$B$5:$M$44,7,FALSE)+VLOOKUP($B18,'Tarifas e Resoluções'!$B$5:$M$44,8,FALSE)) -> 2.38718 | I18: =IFERROR(H18/(1-E18)/(1-D18),"") -> 3.0644159 | J18: =IFERROR(I18/G18-1,"") -> 0.044736013 | L18: =VLOOKUP(N18,Rascunho!$E$4:$G$43,2,FALSE) -> RGE Sul | M18: =VLOOKUP(N18,Rascunho!$E$4:$G$43,3,FALSE) -> RS | N18: =LARGE(Rascunho!$E$4:$E$43,14) -> 3.0202536
B19: ='Tarifas e Resoluções'!B19 -> Equatorial AL | C19: AL | D19: =VLOOKUP(C19,Rascunho!$B$3:$C$29,2,FALSE) -> 0.2 | E19: =E18 -> 0.05 | F19: =VLOOKUP($B19,'Tarifas e Resoluções'!$B$5:$M$44,2,FALSE)+VLOOKUP($B19,'Tarifas e Resoluções'!$B$5:$M$44,3,FALSE) -> 2.2295 | G19: =F19/(1-E19)/(1-D19) -> 2.9335526 | H19: =IF(VLOOKUP($B19,'Tarifas e Resoluções'!$B$5:$M$44,7,FALSE)="","",VLOOKUP($B19,'Tarifas e Resoluções'!$B$5:$M$44,7,FALSE)+VLOOKUP($B19,'Tarifas e Resoluções'!$B$5:$M$44,8,FALSE)) -> 2.25833 | I19: =IFERROR(H19/(1-E19)/(1-D19),"") -> 2.9714868 | J19: =IFERROR(I19/G19-1,"") -> 0.01293115 | L19: =VLOOKUP(N19,Rascunho!$E$4:$G$43,2,FALSE) -> Equatorial AL | M19: =VLOOKUP(N19,Rascunho!$E$4:$G$43,3,FALSE) -> AL | N19: =LARGE(Rascunho!$E$4:$E$43,15) -> 2.9714868
B20: ='Tarifas e Resoluções'!B20 -> COCEL | C20: PR | D20: =VLOOKUP(C20,Rascunho!$B$3:$C$29,2,FALSE) -> 0.195 | E20: =E19 -> 0.05 | F20: =VLOOKUP($B20,'Tarifas e Resoluções'!$B$5:$M$44,2,FALSE)+VLOOKUP($B20,'Tarifas e Resoluções'!$B$5:$M$44,3,FALSE) -> 1.50723 | G20: =F20/(1-E20)/(1-D20) -> 1.9708794 | H20: =IF(VLOOKUP($B20,'Tarifas e Resoluções'!$B$5:$M$44,7,FALSE)="","",VLOOKUP($B20,'Tarifas e Resoluções'!$B$5:$M$44,7,FALSE)+VLOOKUP($B20,'Tarifas e Resoluções'!$B$5:$M$44,8,FALSE)) -> 1.8448 | I20: =IFERROR(H20/(1-E20)/(1-D20),"") -> 2.4122916 | J20: =IFERROR(I20/G20-1,"") -> 0.22396715 | L20: =VLOOKUP(N20,Rascunho!$E$4:$G$43,2,FALSE) -> Energisa MT (EMT) | M20: =VLOOKUP(N20,Rascunho!$E$4:$G$43,3,FALSE) -> MT | N20: =LARGE(Rascunho!$E$4:$E$43,16) -> 2.9133545
B21: ='Tarifas e Resoluções'!B21 -> RGE Sul | C21: RS | D21: =VLOOKUP(C21,Rascunho!$B$3:$C$29,2,FALSE) -> 0.17 | E21: =E20 -> 0.05 | F21: =VLOOKUP($B21,'Tarifas e Resoluções'!$B$5:$M$44,2,FALSE)+VLOOKUP($B21,'Tarifas e Resoluções'!$B$5:$M$44,3,FALSE) -> 2.15126 | G21: =F21/(1-E21)/(1-D21) -> 2.7282942 | H21: =IF(VLOOKUP($B21,'Tarifas e Resoluções'!$B$5:$M$44,7,FALSE)="","",VLOOKUP($B21,'Tarifas e Resoluções'!$B$5:$M$44,7,FALSE)+VLOOKUP($B21,'Tarifas e Resoluções'!$B$5:$M$44,8,FALSE)) -> 2.38147 | I21: =IFERROR(H21/(1-E21)/(1-D21),"") -> 3.0202536 | J21: =IFERROR(I21/G21-1,"") -> 0.1070117 | L21: =VLOOKUP(N21,Rascunho!$E$4:$G$43,2,FALSE) -> Energisa SE (ESE) | M21: =VLOOKUP(N21,Rascunho!$E$4:$G$43,3,FALSE) -> SE | N21: =LARGE(Rascunho!$E$4:$E$43,17) -> 2.8709079
B22: ='Tarifas e Resoluções'!B22 -> Equatorial GO | C22: GO | D22: =VLOOKUP(C22,Rascunho!$B$3:$C$29,2,FALSE) -> 0.19 | E22: =E21 -> 0.05 | F22: =VLOOKUP($B22,'Tarifas e Resoluções'!$B$5:$M$44,2,FALSE)+VLOOKUP($B22,'Tarifas e Resoluções'!$B$5:$M$44,3,FALSE) -> 2.14105 | G22: =F22/(1-E22)/(1-D22) -> 2.7823912 | H22: =IF(VLOOKUP($B22,'Tarifas e Resoluções'!$B$5:$M$44,7,FALSE)="","",VLOOKUP($B22,'Tarifas e Resoluções'!$B$5:$M$44,7,FALSE)+VLOOKUP($B22,'Tarifas e Resoluções'!$B$5:$M$44,8,FALSE)) | I22: =IFERROR(H22/(1-E22)/(1-D22),"") | J22: =IFERROR(I22/G22-1,"") | L22: =VLOOKUP(N22,Rascunho!$E$4:$G$43,2,FALSE) -> Neoenergia Elektro (ELEKTRO) | M22: =VLOOKUP(N22,Rascunho!$E$4:$G$43,3,FALSE) -> SP | N22: =LARGE(Rascunho!$E$4:$E$43,18) -> 2.8291913
B23: ='Tarifas e Resoluções'!B23 -> Neoenergia RN (COSERN) | C23: RN | D23: =VLOOKUP(C23,Rascunho!$B$3:$C$29,2,FALSE) -> 0.18 | E23: =E22 -> 0.05 | F23: =VLOOKUP($B23,'Tarifas e Resoluções'!$B$5:$M$44,2,FALSE)+VLOOKUP($B23,'Tarifas e Resoluções'!$B$5:$M$44,3,FALSE) -> 2.35359 | G23: =F23/(1-E23)/(1-D23) -> 3.0212965 | H23: =IF(VLOOKUP($B23,'Tarifas e Resoluções'!$B$5:$M$44,7,FALSE)="","",VLOOKUP($B23,'Tarifas e Resoluções'!$B$5:$M$44,7,FALSE)+VLOOKUP($B23,'Tarifas e Resoluções'!$B$5:$M$44,8,FALSE)) -> 2.49522 | I23: =IFERROR(H23/(1-E23)/(1-D23),"") -> 3.2031065 | J23: =IFERROR(I23/G23-1,"") -> 0.060176156 | L23: =VLOOKUP(N23,Rascunho!$E$4:$G$43,2,FALSE) -> CPFL Santa Cruz | M23: =VLOOKUP(N23,Rascunho!$E$4:$G$43,3,FALSE) -> SP | N23: =LARGE(Rascunho!$E$4:$E$43,19) -> 2.8220154
B24: ='Tarifas e Resoluções'!B24 -> CELESC | C24: SC | D24: =VLOOKUP(C24,Rascunho!$B$3:$C$29,2,FALSE) -> 0.17 | E24: =E23 -> 0.05 | F24: =VLOOKUP($B24,'Tarifas e Resoluções'!$B$5:$M$44,2,FALSE)+VLOOKUP($B24,'Tarifas e Resoluções'!$B$5:$M$44,3,FALSE) -> 1.55304 | G24: =F24/(1-E24)/(1-D24) -> 1.9696132 | H24: =IF(VLOOKUP($B24,'Tarifas e Resoluções'!$B$5:$M$44,7,FALSE)="","",VLOOKUP($B24,'Tarifas e Resoluções'!$B$5:$M$44,7,FALSE)+VLOOKUP($B24,'Tarifas e Resoluções'!$B$5:$M$44,8,FALSE)) -> 1.71635 | I24: =IFERROR(H24/(1-E24)/(1-D24),"") -> 2.176728 | J24: =IFERROR(I24/G24-1,"") -> 0.10515505 | L24: =VLOOKUP(N24,Rascunho!$E$4:$G$43,2,FALSE) -> Roraima Energia (Boa Vista) | M24: =VLOOKUP(N24,Rascunho!$E$4:$G$43,3,FALSE) -> RR | N24: =LARGE(Rascunho!$E$4:$E$43,20) -> 2.8059079
B25: ='Tarifas e Resoluções'!B25 -> Roraima Energia (Boa Vista) | C25: RR | D25: =VLOOKUP(C25,Rascunho!$B$3:$C$29,2,FALSE) -> 0.2 | E25: =E24 -> 0.05 | F25: =VLOOKUP($B25,'Tarifas e Resoluções'!$B$5:$M$44,2,FALSE)+VLOOKUP($B25,'Tarifas e Resoluções'!$B$5:$M$44,3,FALSE) -> 1.76787 | G25: =F25/(1-E25)/(1-D25) -> 2.3261447 | H25: =IF(VLOOKUP($B25,'Tarifas e Resoluções'!$B$5:$M$44,7,FALSE)="","",VLOOKUP($B25,'Tarifas e Resoluções'!$B$5:$M$44,7,FALSE)+VLOOKUP($B25,'Tarifas e Resoluções'!$B$5:$M$44,8,FALSE)) -> 2.13249 | I25: =IFERROR(H25/(1-E25)/(1-D25),"") -> 2.8059079 | J25: =IFERROR(I25/G25-1,"") -> 0.2062482 | L25: =VLOOKUP(N25,Rascunho!$E$4:$G$43,2,FALSE) -> Equatorial GO | M25: =VLOOKUP(N25,Rascunho!$E$4:$G$43,3,FALSE) -> GO | N25: =LARGE(Rascunho!$E$4:$E$43,21) -> 2.7823912
B26: ='Tarifas e Resoluções'!B26 -> Neoenergia Elektro (ELEKTRO) | C26: SP | D26: =VLOOKUP(C26,Rascunho!$B$3:$C$29,2,FALSE) -> 0.18 | E26: =E25 -> 0.05 | F26: =VLOOKUP($B26,'Tarifas e Resoluções'!$B$5:$M$44,2,FALSE)+VLOOKUP($B26,'Tarifas e Resoluções'!$B$5:$M$44,3,FALSE) -> 2.40313 | G26: =F26/(1-E26)/(1-D26) -> 3.0848909 | H26: =IF(VLOOKUP($B26,'Tarifas e Resoluções'!$B$5:$M$44,7,FALSE)="","",VLOOKUP($B26,'Tarifas e Resoluções'!$B$5:$M$44,7,FALSE)+VLOOKUP($B26,'Tarifas e Resoluções'!$B$5:$M$44,8,FALSE)) -> 2.20394 | I26: =IFERROR(H26/(1-E26)/(1-D26),"") -> 2.8291913 | J26: =IFERROR(I26/G26-1,"") -> -0.082887734 | L26: =VLOOKUP(N26,Rascunho!$E$4:$G$43,2,FALSE) -> CEEE Equatorial | M26: =VLOOKUP(N26,Rascunho!$E$4:$G$43,3,FALSE) -> RS | N26: =LARGE(Rascunho!$E$4:$E$43,22) -> 2.7568294
B27: ='Tarifas e Resoluções'!B27 -> COPEL | C27: PR | D27: =VLOOKUP(C27,Rascunho!$B$3:$C$29,2,FALSE) -> 0.195 | E27: =E26 -> 0.05 | F27: =VLOOKUP($B27,'Tarifas e Resoluções'!$B$5:$M$44,2,FALSE)+VLOOKUP($B27,'Tarifas e Resoluções'!$B$5:$M$44,3,FALSE) -> 1.62525 | G27: =F27/(1-E27)/(1-D27) -> 2.1252043 | H27: =IF(VLOOKUP($B27,'Tarifas e Resoluções'!$B$5:$M$44,7,FALSE)="","",VLOOKUP($B27,'Tarifas e Resoluções'!$B$5:$M$44,7,FALSE)+VLOOKUP($B27,'Tarifas e Resoluções'!$B$5:$M$44,8,FALSE)) -> 1.93894 | I27: =IFERROR(H27/(1-E27)/(1-D27),"") -> 2.5353907 | J27: =IFERROR(I27/G27-1,"") -> 0.19301031 | L27: =VLOOKUP(N27,Rascunho!$E$4:$G$43,2,FALSE) -> SULGIPE | M27: =VLOOKUP(N27,Rascunho!$E$4:$G$43,3,FALSE) -> SE | N27: =LARGE(Rascunho!$E$4:$E$43,23) -> 2.7433026
B28: ='Tarifas e Resoluções'!B28 -> Enel CE | C28: CE | D28: =VLOOKUP(C28,Rascunho!$B$3:$C$29,2,FALSE) -> 0.2 | E28: =E27 -> 0.05 | F28: =VLOOKUP($B28,'Tarifas e Resoluções'!$B$5:$M$44,2,FALSE)+VLOOKUP($B28,'Tarifas e Resoluções'!$B$5:$M$44,3,FALSE) -> 1.53537 | G28: =F28/(1-E28)/(1-D28) -> 2.0202237 | H28: =IF(VLOOKUP($B28,'Tarifas e Resoluções'!$B$5:$M$44,7,FALSE)="","",VLOOKUP($B28,'Tarifas e Resoluções'!$B$5:$M$44,7,FALSE)+VLOOKUP($B28,'Tarifas e Resoluções'!$B$5:$M$44,8,FALSE)) -> 1.54397 | I28: =IFERROR(H28/(1-E28)/(1-D28),"") -> 2.0315395 | J28: =IFERROR(I28/G28-1,"") -> 0.0056012557 | L28: =VLOOKUP(N28,Rascunho!$E$4:$G$43,2,FALSE) -> CHESP | M28: =VLOOKUP(N28,Rascunho!$E$4:$G$43,3,FALSE) -> GO | N28: =LARGE(Rascunho!$E$4:$E$43,24) -> 2.7124886
B29: ='Tarifas e Resoluções'!B29 -> Energisa SE (ESE) | C29: SE | D29: =VLOOKUP(C29,Rascunho!$B$3:$C$29,2,FALSE) -> 0.2 | E29: =E28 -> 0.05 | F29: =VLOOKUP($B29,'Tarifas e Resoluções'!$B$5:$M$44,2,FALSE)+VLOOKUP($B29,'Tarifas e Resoluções'!$B$5:$M$44,3,FALSE) -> 2.12944 | G29: =F29/(1-E29)/(1-D29) -> 2.8018947 | H29: =IF(VLOOKUP($B29,'Tarifas e Resoluções'!$B$5:$M$44,7,FALSE)="","",VLOOKUP($B29,'Tarifas e Resoluções'!$B$5:$M$44,7,FALSE)+VLOOKUP($B29,'Tarifas e Resoluções'!$B$5:$M$44,8,FALSE)) -> 2.18189 | I29: =IFERROR(H29/(1-E29)/(1-D29),"") -> 2.8709079 | J29: =IFERROR(I29/G29-1,"") -> 0.024630889 | L29: =VLOOKUP(N29,Rascunho!$E$4:$G$43,2,FALSE) -> COPEL | M29: =VLOOKUP(N29,Rascunho!$E$4:$G$43,3,FALSE) -> PR | N29: =LARGE(Rascunho!$E$4:$E$43,25) -> 2.5353907
B30: ='Tarifas e Resoluções'!B30 -> CEEE Equatorial | C30: RS | D30: =VLOOKUP(C30,Rascunho!$B$3:$C$29,2,FALSE) -> 0.17 | E30: =E29 -> 0.05 | F30: =VLOOKUP($B30,'Tarifas e Resoluções'!$B$5:$M$44,2,FALSE)+VLOOKUP($B30,'Tarifas e Resoluções'!$B$5:$M$44,3,FALSE) -> 2.17376 | G30: =F30/(1-E30)/(1-D30) -> 2.7568294 | H30: =IF(VLOOKUP($B30,'Tarifas e Resoluções'!$B$5:$M$44,7,FALSE)="","",VLOOKUP($B30,'Tarifas e Resoluções'!$B$5:$M$44,7,FALSE)+VLOOKUP($B30,'Tarifas e Resoluções'!$B$5:$M$44,8,FALSE)) | I30: =IFERROR(H30/(1-E30)/(1-D30),"") | J30: =IFERROR(I30/G30-1,"") | L30: =VLOOKUP(N30,Rascunho!$E$4:$G$43,2,FALSE) -> EDP ES | M30: =VLOOKUP(N30,Rascunho!$E$4:$G$43,3,FALSE) -> ES | N30: =LARGE(Rascunho!$E$4:$E$43,26) -> 2.4406088
B31: ='Tarifas e Resoluções'!B31 -> CPFL Paulista | C31: SP | D31: =VLOOKUP(C31,Rascunho!$B$3:$C$29,2,FALSE) -> 0.18 | E31: =E30 -> 0.05 | F31: =VLOOKUP($B31,'Tarifas e Resoluções'!$B$5:$M$44,2,FALSE)+VLOOKUP($B31,'Tarifas e Resoluções'!$B$5:$M$44,3,FALSE) -> 1.73913 | G31: =F31/(1-E31)/(1-D31) -> 2.232516 | H31: =IF(VLOOKUP($B31,'Tarifas e Resoluções'!$B$5:$M$44,7,FALSE)="","",VLOOKUP($B31,'Tarifas e Resoluções'!$B$5:$M$44,7,FALSE)+VLOOKUP($B31,'Tarifas e Resoluções'!$B$5:$M$44,8,FALSE)) -> 1.78345 | I31: =IFERROR(H31/(1-E31)/(1-D31),"") -> 2.2894095 | J31: =IFERROR(I31/G31-1,"") -> 0.025484006 | L31: =VLOOKUP(N31,Rascunho!$E$4:$G$43,2,FALSE) -> COCEL | M31: =VLOOKUP(N31,Rascunho!$E$4:$G$43,3,FALSE) -> PR | N31: =LARGE(Rascunho!$E$4:$E$43,27) -> 2.4122916
B32: ='Tarifas e Resoluções'!B32 -> CPFL Piratininga | C32: SP | D32: =VLOOKUP(C32,Rascunho!$B$3:$C$29,2,FALSE) -> 0.18 | E32: =E31 -> 0.05 | F32: =VLOOKUP($B32,'Tarifas e Resoluções'!$B$5:$M$44,2,FALSE)+VLOOKUP($B32,'Tarifas e Resoluções'!$B$5:$M$44,3,FALSE) -> 1.45735 | G32: =F32/(1-E32)/(1-D32) -> 1.8707959 | H32: =IF(VLOOKUP($B32,'Tarifas e Resoluções'!$B$5:$M$44,7,FALSE)="","",VLOOKUP($B32,'Tarifas e Resoluções'!$B$5:$M$44,7,FALSE)+VLOOKUP($B32,'Tarifas e Resoluções'!$B$5:$M$44,8,FALSE)) | I32: =IFERROR(H32/(1-E32)/(1-D32),"") | J32: =IFERROR(I32/G32-1,"") | L32: =VLOOKUP(N32,Rascunho!$E$4:$G$43,2,FALSE) -> Energisa Sul-Sudeste (ESS) | M32: =VLOOKUP(N32,Rascunho!$E$4:$G$43,3,FALSE) -> SP | N32: =LARGE(Rascunho!$E$4:$E$43,28) -> 2.4054942
B33: ='Tarifas e Resoluções'!B33 -> EDP SP | C33: SP | D33: =VLOOKUP(C33,Rascunho!$B$3:$C$29,2,FALSE) -> 0.18 | E33: =E32 -> 0.05 | F33: =VLOOKUP($B33,'Tarifas e Resoluções'!$B$5:$M$44,2,FALSE)+VLOOKUP($B33,'Tarifas e Resoluções'!$B$5:$M$44,3,FALSE) -> 1.81466 | G33: =F33/(1-E33)/(1-D33) -> 2.3294737 | H33: =IF(VLOOKUP($B33,'Tarifas e Resoluções'!$B$5:$M$44,7,FALSE)="","",VLOOKUP($B33,'Tarifas e Resoluções'!$B$5:$M$44,7,FALSE)+VLOOKUP($B33,'Tarifas e Resoluções'!$B$5:$M$44,8,FALSE)) | I33: =IFERROR(H33/(1-E33)/(1-D33),"") | J33: =IFERROR(I33/G33-1,"") | L33: =VLOOKUP(N33,Rascunho!$E$4:$G$43,2,FALSE) -> Amazonas Energia | M33: =VLOOKUP(N33,Rascunho!$E$4:$G$43,3,FALSE) -> AM | N33: =LARGE(Rascunho!$E$4:$E$43,29) -> 2.3751447
B34: ='Tarifas e Resoluções'!B34 -> Neoenergia Brasília (CEB) | C34: DF | D34: =VLOOKUP(C34,Rascunho!$B$3:$C$29,2,FALSE) -> 0.2 | E34: =E33 -> 0.05 | F34: =VLOOKUP($B34,'Tarifas e Resoluções'!$B$5:$M$44,2,FALSE)+VLOOKUP($B34,'Tarifas e Resoluções'!$B$5:$M$44,3,FALSE) -> 1.52977 | G34: =F34/(1-E34)/(1-D34) -> 2.0128553 | H34: =IF(VLOOKUP($B34,'Tarifas e Resoluções'!$B$5:$M$44,7,FALSE)="","",VLOOKUP($B34,'Tarifas e Resoluções'!$B$5:$M$44,7,FALSE)+VLOOKUP($B34,'Tarifas e Resoluções'!$B$5:$M$44,8,FALSE)) | I34: =IFERROR(H34/(1-E34)/(1-D34),"") | J34: =IFERROR(I34/G34-1,"") | L34: =VLOOKUP(N34,Rascunho!$E$4:$G$43,2,FALSE) -> EDP SP | M34: =VLOOKUP(N34,Rascunho!$E$4:$G$43,3,FALSE) -> SP | N34: =LARGE(Rascunho!$E$4:$E$43,30) -> 2.3294737
B35: ='Tarifas e Resoluções'!B35 -> Enel RJ | C35: RJ | D35: =VLOOKUP(C35,Rascunho!$B$3:$C$29,2,FALSE) -> 0.22 | E35: =E34 -> 0.05 | F35: =VLOOKUP($B35,'Tarifas e Resoluções'!$B$5:$M$44,2,FALSE)+VLOOKUP($B35,'Tarifas e Resoluções'!$B$5:$M$44,3,FALSE) -> 2.37997 | G35: =F35/(1-E35)/(1-D35) -> 3.2118354 | H35: =IF(VLOOKUP($B35,'Tarifas e Resoluções'!$B$5:$M$44,7,FALSE)="","",VLOOKUP($B35,'Tarifas e Resoluções'!$B$5:$M$44,7,FALSE)+VLOOKUP($B35,'Tarifas e Resoluções'!$B$5:$M$44,8,FALSE)) -> 2.54698 | I35: =IFERROR(H35/(1-E35)/(1-D35),"") -> 3.43722 | J35: =IFERROR(I35/G35-1,"") -> 0.070173153 | L35: =VLOOKUP(N35,Rascunho!$E$4:$G$43,2,FALSE) -> CPFL Paulista | M35: =VLOOKUP(N35,Rascunho!$E$4:$G$43,3,FALSE) -> SP | N35: =LARGE(Rascunho!$E$4:$E$43,31) -> 2.2894095
B36: ='Tarifas e Resoluções'!B36 -> Enel SP (ELETROPAULO) | C36: SP | D36: =VLOOKUP(C36,Rascunho!$B$3:$C$29,2,FALSE) -> 0.18 | E36: =E35 -> 0.05 | F36: =VLOOKUP($B36,'Tarifas e Resoluções'!$B$5:$M$44,2,FALSE)+VLOOKUP($B36,'Tarifas e Resoluções'!$B$5:$M$44,3,FALSE) -> 1.2762 | G36: =F36/(1-E36)/(1-D36) -> 1.6382542 | H36: =IF(VLOOKUP($B36,'Tarifas e Resoluções'!$B$5:$M$44,7,FALSE)="","",VLOOKUP($B36,'Tarifas e Resoluções'!$B$5:$M$44,7,FALSE)+VLOOKUP($B36,'Tarifas e Resoluções'!$B$5:$M$44,8,FALSE)) -> 1.40483 | I36: =IFERROR(H36/(1-E36)/(1-D36),"") -> 1.8033761 | J36: =IFERROR(I36/G36-1,"") -> 0.10079141 | L36: =VLOOKUP(N36,Rascunho!$E$4:$G$43,2,FALSE) -> Energisa PB (EPB) | M36: =VLOOKUP(N36,Rascunho!$E$4:$G$43,3,FALSE) -> PB | N36: =LARGE(Rascunho!$E$4:$E$43,32) -> 2.2606447
B37: ='Tarifas e Resoluções'!B37 -> Amazonas Energia | C37: AM | D37: =VLOOKUP(C37,Rascunho!$B$3:$C$29,2,FALSE) -> 0.2 | E37: =E36 -> 0.05 | F37: =VLOOKUP($B37,'Tarifas e Resoluções'!$B$5:$M$44,2,FALSE)+VLOOKUP($B37,'Tarifas e Resoluções'!$B$5:$M$44,3,FALSE) -> 1.73009 | G37: =F37/(1-E37)/(1-D37) -> 2.2764342 | H37: =IF(VLOOKUP($B37,'Tarifas e Resoluções'!$B$5:$M$44,7,FALSE)="","",VLOOKUP($B37,'Tarifas e Resoluções'!$B$5:$M$44,7,FALSE)+VLOOKUP($B37,'Tarifas e Resoluções'!$B$5:$M$44,8,FALSE)) -> 1.80511 | I37: =IFERROR(H37/(1-E37)/(1-D37),"") -> 2.3751447 | J37: =IFERROR(I37/G37-1,"") -> 0.043361906 | L37: =VLOOKUP(N37,Rascunho!$E$4:$G$43,2,FALSE) -> FORCEL (Pacto Energia PR) | M37: =VLOOKUP(N37,Rascunho!$E$4:$G$43,3,FALSE) -> PR | N37: =LARGE(Rascunho!$E$4:$E$43,33) -> 2.2263354
B38: ='Tarifas e Resoluções'!B38 -> Energisa Sul-Sudeste (ESS) | C38: SP | D38: =VLOOKUP(C38,Rascunho!$B$3:$C$29,2,FALSE) -> 0.18 | E38: =E37 -> 0.05 | F38: =VLOOKUP($B38,'Tarifas e Resoluções'!$B$5:$M$44,2,FALSE)+VLOOKUP($B38,'Tarifas e Resoluções'!$B$5:$M$44,3,FALSE) -> 1.72994 | G38: =F38/(1-E38)/(1-D38) -> 2.2207189 | H38: =IF(VLOOKUP($B38,'Tarifas e Resoluções'!$B$5:$M$44,7,FALSE)="","",VLOOKUP($B38,'Tarifas e Resoluções'!$B$5:$M$44,7,FALSE)+VLOOKUP($B38,'Tarifas e Resoluções'!$B$5:$M$44,8,FALSE)) -> 1.87388 | I38: =IFERROR(H38/(1-E38)/(1-D38),"") -> 2.4054942 | J38: =IFERROR(I38/G38-1,"") -> 0.083205198 | L38: =VLOOKUP(N38,Rascunho!$E$4:$G$43,2,FALSE) -> LIGHT (LIGHT SESA) | M38: =VLOOKUP(N38,Rascunho!$E$4:$G$43,3,FALSE) -> RJ | N38: =LARGE(Rascunho!$E$4:$E$43,34) -> 2.1777868
B39: ='Tarifas e Resoluções'!B39 -> Equatorial AP (CEA) | C39: AP | D39: =VLOOKUP(C39,Rascunho!$B$3:$C$29,2,FALSE) -> 0.18 | E39: =E38 -> 0.05 | F39: =VLOOKUP($B39,'Tarifas e Resoluções'!$B$5:$M$44,2,FALSE)+VLOOKUP($B39,'Tarifas e Resoluções'!$B$5:$M$44,3,FALSE) -> 2.64311 | G39: =F39/(1-E39)/(1-D39) -> 3.3929525 | H39: =IF(VLOOKUP($B39,'Tarifas e Resoluções'!$B$5:$M$44,7,FALSE)="","",VLOOKUP($B39,'Tarifas e Resoluções'!$B$5:$M$44,7,FALSE)+VLOOKUP($B39,'Tarifas e Resoluções'!$B$5:$M$44,8,FALSE)) -> 3.26293 | I39: =IFERROR(H39/(1-E39)/(1-D39),"") -> 4.1886136 | J39: =IFERROR(I39/G39-1,"") -> 0.23450405 | L39: =VLOOKUP(N39,Rascunho!$E$4:$G$43,2,FALSE) -> CELESC | M39: =VLOOKUP(N39,Rascunho!$E$4:$G$43,3,FALSE) -> SC | N39: =LARGE(Rascunho!$E$4:$E$43,35) -> 2.176728
B40: ='Tarifas e Resoluções'!B40 -> CHESP | C40: GO | D40: =VLOOKUP(C40,Rascunho!$B$3:$C$29,2,FALSE) -> 0.19 | E40: =E39 -> 0.05 | F40: =VLOOKUP($B40,'Tarifas e Resoluções'!$B$5:$M$44,2,FALSE)+VLOOKUP($B40,'Tarifas e Resoluções'!$B$5:$M$44,3,FALSE) -> 2.08726 | G40: =F40/(1-E40)/(1-D40) -> 2.7124886 | H40: =IF(VLOOKUP($B40,'Tarifas e Resoluções'!$B$5:$M$44,7,FALSE)="","",VLOOKUP($B40,'Tarifas e Resoluções'!$B$5:$M$44,7,FALSE)+VLOOKUP($B40,'Tarifas e Resoluções'!$B$5:$M$44,8,FALSE)) | I40: =IFERROR(H40/(1-E40)/(1-D40),"") | J40: =IFERROR(I40/G40-1,"") | L40: =VLOOKUP(N40,Rascunho!$E$4:$G$43,2,FALSE) -> Neoenergia PE | M40: =VLOOKUP(N40,Rascunho!$E$4:$G$43,3,FALSE) -> PE | N40: =LARGE(Rascunho!$E$4:$E$43,36) -> 2.0731678
B41: ='Tarifas e Resoluções'!B41 -> CPFL Santa Cruz | C41: SP | D41: =VLOOKUP(C41,Rascunho!$B$3:$C$29,2,FALSE) -> 0.18 | E41: =E40 -> 0.05 | F41: =VLOOKUP($B41,'Tarifas e Resoluções'!$B$5:$M$44,2,FALSE)+VLOOKUP($B41,'Tarifas e Resoluções'!$B$5:$M$44,3,FALSE) -> 1.88547 | G41: =F41/(1-E41)/(1-D41) -> 2.4203723 | H41: =IF(VLOOKUP($B41,'Tarifas e Resoluções'!$B$5:$M$44,7,FALSE)="","",VLOOKUP($B41,'Tarifas e Resoluções'!$B$5:$M$44,7,FALSE)+VLOOKUP($B41,'Tarifas e Resoluções'!$B$5:$M$44,8,FALSE)) -> 2.19835 | I41: =IFERROR(H41/(1-E41)/(1-D41),"") -> 2.8220154 | J41: =IFERROR(I41/G41-1,"") -> 0.16594271 | L41: =VLOOKUP(N41,Rascunho!$E$4:$G$43,2,FALSE) -> Enel CE | M41: =VLOOKUP(N41,Rascunho!$E$4:$G$43,3,FALSE) -> CE | N41: =LARGE(Rascunho!$E$4:$E$43,37) -> 2.0315395
...

Sheet Tarifas Ponta Livre
B2: Tarifas Mercado Livre de Energia - Energia I50
B3: Concessionárias | C3: Estado | D3: ICMS | E3: PIS/COFINS | F3: ANTERIOR | H3: ATUAL | J3: Reajuste | L3: RANKING TUSD Ponta - Mercado Livre - I5
F4: TUSD P | H4: TUSD P
F5: S/ Imp | G5: C/ Imp | H5: S/ Imp | I5: C/ Imp | L5: Concessionária | M5: Estado | N5: Tarifa Ponta
B6: ='Tarifas e Resoluções'!B5 -> Equatorial PA | C6: PA | D6: =VLOOKUP(C6,Rascunho!$B$3:$C$29,2,FALSE) -> 0.19 | E6: 0.05 | F6: =((VLOOKUP($B6,'Tarifas e Resoluções'!$B$5:$M$44,2,FALSE)-VLOOKUP($B6,'Tarifas e Resoluções'!$B$5:$M$44,4,FALSE))*0.5)+VLOOKUP($B6,'Tarifas e Resoluções'!$B$5:$M$44,4,FALSE) -> 1.36722 | G6: =F6/(1-E6)/(1-D6)+((VLOOKUP($B6,'Tarifas e Resoluções'!$B$5:$M$44,2,FALSE)-F6)/(1-E6)/(1-D6)-(VLOOKUP($B6,'Tarifas e Resoluções'!$B$5:$M$44,2,FALSE)-F6)) -> 2.1408193 | H6: =IF(VLOOKUP($B6,'Tarifas e Resoluções'!$B$5:$M$44,7,FALSE)="","",((VLOOKUP($B6,'Tarifas e Resoluções'!$B$5:$M$44,7,FALSE)-VLOOKUP($B6,'Tarifas e Resoluções'!$B$5:$M$44,9,FALSE))*0.5)+VLOOKUP($B6,'Tarifas e Resoluções'!$B$5:$M$44,9,FALSE)) -> 1.35622 | I6: =IFERROR(H6/(1-E6)/(1-D6)+((VLOOKUP($B6,'Tarifas e Resoluções'!$B$5:$M$44,7,FALSE)-H6)/(1-E6)/(1-D6)-(VLOOKUP($B6,'Tarifas e Resoluções'!$B$5:$M$44,7,FALSE)-H6)),"") -> 2.1112146 | J6: =IFERROR(I6/G6-1,"") -> -0.013828701 | L6: =VLOOKUP(N6,Rascunho!$I$4:$K$43,2,FALSE) -> Equatorial AP (CEA) | M6: =VLOOKUP(N6,Rascunho!$I$4:$K$43,3,FALSE) -> AP | N6: =LARGE(Rascunho!$I$4:$I$43,1) -> 2.4825868 | O6: 1
B7: ='Tarifas e Resoluções'!B6 -> Energisa TO (ETO) | C7: TO | D7: =VLOOKUP(C7,Rascunho!$B$3:$C$29,2,FALSE) -> 0.2 | E7: =E6 -> 0.05 | F7: =((VLOOKUP($B7,'Tarifas e Resoluções'!$B$5:$M$44,2,FALSE)-VLOOKUP($B7,'Tarifas e Resoluções'!$B$5:$M$44,4,FALSE))*0.5)+VLOOKUP($B7,'Tarifas e Resoluções'!$B$5:$M$44,4,FALSE) -> 1.07247 | G7: =F7/(1-E7)/(1-D7)+((VLOOKUP($B7,'Tarifas e Resoluções'!$B$5:$M$44,2,FALSE)-F7)/(1-E7)/(1-D7)-(VLOOKUP($B7,'Tarifas e Resoluções'!$B$5:$M$44,2,FALSE)-F7)) -> 1.7160521 | H7: =IF(VLOOKUP($B7,'Tarifas e Resoluções'!$B$5:$M$44,7,FALSE)="","",((VLOOKUP($B7,'Tarifas e Resoluções'!$B$5:$M$44,7,FALSE)-VLOOKUP($B7,'Tarifas e Resoluções'!$B$5:$M$44,9,FALSE))*0.5)+VLOOKUP($B7,'Tarifas e Resoluções'!$B$5:$M$44,9,FALSE)) -> 1.110235 | I7: =IFERROR(H7/(1-E7)/(1-D7)+((VLOOKUP($B7,'Tarifas e Resoluções'!$B$5:$M$44,7,FALSE)-H7)/(1-E7)/(1-D7)-(VLOOKUP($B7,'Tarifas e Resoluções'!$B$5:$M$44,7,FALSE)-H7)),"") -> 1.7695939 | J7: =IFERROR(I7/G7-1,"") -> 0.031200592 | L7: =VLOOKUP(N7,Rascunho!$I$4:$K$43,2,FALSE) -> Energisa AC (EAC) | M7: =VLOOKUP(N7,Rascunho!$I$4:$K$43,3,FALSE) -> AC | N7: =LARGE(Rascunho!$I$4:$I$43,2) -> 2.273492 | O7: 2
B8: ='Tarifas e Resoluções'!B7 -> Equatorial MA | C8: MA | D8: =VLOOKUP(C8,Rascunho!$B$3:$C$29,2,FALSE) -> 0.22 | E8: =E7 -> 0.05 | F8: =((VLOOKUP($B8,'Tarifas e Resoluções'!$B$5:$M$44,2,FALSE)-VLOOKUP($B8,'Tarifas e Resoluções'!$B$5:$M$44,4,FALSE))*0.5)+VLOOKUP($B8,'Tarifas e Resoluções'!$B$5:$M$44,4,FALSE) -> 1.24681 | G8: =F8/(1-E8)/(1-D8)+((VLOOKUP($B8,'Tarifas e Resoluções'!$B$5:$M$44,2,FALSE)-F8)/(1-E8)/(1-D8)-(VLOOKUP($B8,'Tarifas e Resoluções'!$B$5:$M$44,2,FALSE)-F8)) -> 2.0778015 | H8: =IF(VLOOKUP($B8,'Tarifas e Resoluções'!$B$5:$M$44,7,FALSE)="","",((VLOOKUP($B8,'Tarifas e Resoluções'!$B$5:$M$44,7,FALSE)-VLOOKUP($B8,'Tarifas e Resoluções'!$B$5:$M$44,9,FALSE))*0.5)+VLOOKUP($B8,'Tarifas e Resoluções'!$B$5:$M$44,9,FALSE)) -> 1.274185 | I8: =IFERROR(H8/(1-E8)/(1-D8)+((VLOOKUP($B8,'Tarifas e Resoluções'!$B$5:$M$44,7,FALSE)-H8)/(1-E8)/(1-D8)-(VLOOKUP($B8,'Tarifas e Resoluções'!$B$5:$M$44,7,FALSE)-H8)),"") -> 2.1106886 | J8: =IFERROR(I8/G8-1,"") -> 0.015827812 | L8: =VLOOKUP(N8,Rascunho!$I$4:$K$43,2,FALSE) -> Energisa RO (ERO) | M8: =VLOOKUP(N8,Rascunho!$I$4:$K$43,3,FALSE) -> RO | N8: =LARGE(Rascunho!$I$4:$I$43,3) -> 2.1202749 | O8: 3
B9: ='Tarifas e Resoluções'!B8 -> Energisa AC (EAC) | C9: AC | D9: =VLOOKUP(C9,Rascunho!$B$3:$C$29,2,FALSE) -> 0.19 | E9: =E8 -> 0.05 | F9: =((VLOOKUP($B9,'Tarifas e Resoluções'!$B$5:$M$44,2,FALSE)-VLOOKUP($B9,'Tarifas e Resoluções'!$B$5:$M$44,4,FALSE))*0.5)+VLOOKUP($B9,'Tarifas e Resoluções'!$B$5:$M$44,4,FALSE) -> 1.4486465 | G9: =F9/(1-E9)/(1-D9)+((VLOOKUP($B9,'Tarifas e Resoluções'!$B$5:$M$44,2,FALSE)-F9)/(1-E9)/(1-D9)-(VLOOKUP($B9,'Tarifas e Resoluções'!$B$5:$M$44,2,FALSE)-F9)) -> 2.273492 | H9: =IF(VLOOKUP($B9,'Tarifas e Resoluções'!$B$5:$M$44,7,FALSE)="","",((VLOOKUP($B9,'Tarifas e Resoluções'!$B$5:$M$44,7,FALSE)-VLOOKUP($B9,'Tarifas e Resoluções'!$B$5:$M$44,9,FALSE))*0.5)+VLOOKUP($B9,'Tarifas e Resoluções'!$B$5:$M$44,9,FALSE)) | I9: =IFERROR(H9/(1-E9)/(1-D9)+((VLOOKUP($B9,'Tarifas e Resoluções'!$B$5:$M$44,7,FALSE)-H9)/(1-E9)/(1-D9)-(VLOOKUP($B9,'Tarifas e Resoluções'!$B$5:$M$44,7,FALSE)-H9)),"") | J9: =IFERROR(I9/G9-1,"") | L9: =VLOOKUP(N9,Rascunho!$I$4:$K$43,2,FALSE) -> Equatorial PA | M9: =VLOOKUP(N9,Rascunho!$I$4:$K$43,3,FALSE) -> PA | N9: =LARGE(Rascunho!$I$4:$I$43,4) -> 2.1112146 | O9: 4
B10: ='Tarifas e Resoluções'!B9 -> Energisa RO (ERO) | C10: RO | D10: =VLOOKUP(C10,Rascunho!$B$3:$C$29,2,FALSE) -> 0.195 | E10: =E9 -> 0.05 | F10: =((VLOOKUP($B10,'Tarifas e Resoluções'!$B$5:$M$44,2,FALSE)-VLOOKUP($B10,'Tarifas e Resoluções'!$B$5:$M$44,4,FALSE))*0.5)+VLOOKUP($B10,'Tarifas e Resoluções'!$B$5:$M$44,4,FALSE) -> 1.342035 | G10: =F10/(1-E10)/(1-D10)+((VLOOKUP($B10,'Tarifas e Resoluções'!$B$5:$M$44,2,FALSE)-F10)/(1-E10)/(1-D10)-(VLOOKUP($B10,'Tarifas e Resoluções'!$B$5:$M$44,2,FALSE)-F10)) -> 2.1202749 | H10: =IF(VLOOKUP($B10,'Tarifas e Resoluções'!$B$5:$M$44,7,FALSE)="","",((VLOOKUP($B10,'Tarifas e Resoluções'!$B$5:$M$44,7,FALSE)-VLOOKUP($B10,'Tarifas e Resoluções'!$B$5:$M$44,9,FALSE))*0.5)+VLOOKUP($B10,'Tarifas e Resoluções'!$B$5:$M$44,9,FALSE)) | I10: =IFERROR(H10/(1-E10)/(1-D10)+((VLOOKUP($B10,'Tarifas e Resoluções'!$B$5:$M$44,7,FALSE)-H10)/(1-E10)/(1-D10)-(VLOOKUP($B10,'Tarifas e Resoluções'!$B$5:$M$44,7,FALSE)-H10)),"") | J10: =IFERROR(I10/G10-1,"") | L10: =VLOOKUP(N10,Rascunho!$I$4:$K$43,2,FALSE) -> Equatorial MA | M10: =VLOOKUP(N10,Rascunho!$I$4:$K$43,3,FALSE) -> MA | N10: =LARGE(Rascunho!$I$4:$I$43,5) -> 2.1106886 | O10: 5
B11: ='Tarifas e Resoluções'!B10 -> LIGHT (LIGHT SESA) | C11: RJ | D11: =VLOOKUP(C11,Rascunho!$B$3:$C$29,2,FALSE) -> 0.22 | E11: =E10 -> 0.05 | F11: =((VLOOKUP($B11,'Tarifas e Resoluções'!$B$5:$M$44,2,FALSE)-VLOOKUP($B11,'Tarifas e Resoluções'!$B$5:$M$44,4,FALSE))*0.5)+VLOOKUP($B11,'Tarifas e Resoluções'!$B$5:$M$44,4,FALSE) -> 0.642155 | G11: =F11/(1-E11)/(1-D11)+((VLOOKUP($B11,'Tarifas e Resoluções'!$B$5:$M$44,2,FALSE)-F11)/(1-E11)/(1-D11)-(VLOOKUP($B11,'Tarifas e Resoluções'!$B$5:$M$44,2,FALSE)-F11)) -> 1.0346082 | H11: =IF(VLOOKUP($B11,'Tarifas e Resoluções'!$B$5:$M$44,7,FALSE)="","",((VLOOKUP($B11,'Tarifas e Resoluções'!$B$5:$M$44,7,FALSE)-VLOOKUP($B11,'Tarifas e Resoluções'!$B$5:$M$44,9,FALSE))*0.5)+VLOOKUP($B11,'Tarifas e Resoluções'!$B$5:$M$44,9,FALSE)) -> 0.695665 | I11: =IFERROR(H11/(1-E11)/(1-D11)+((VLOOKUP($B11,'Tarifas e Resoluções'!$B$5:$M$44,7,FALSE)-H11)/(1-E11)/(1-D11)-(VLOOKUP($B11,'Tarifas e Resoluções'!$B$5:$M$44,7,FALSE)-H11)),"") -> 1.1068214 | J11: =IFERROR(I11/G11-1,"") -> 0.069797657 | L11: =VLOOKUP(N11,Rascunho!$I$4:$K$43,2,FALSE) -> Equatorial PI | M11: =VLOOKUP(N11,Rascunho!$I$4:$K$43,3,FALSE) -> PI | N11: =LARGE(Rascunho!$I$4:$I$43,6) -> 2.0411516 | O11: 6
B12: ='Tarifas e Resoluções'!B11 -> Energisa MT (EMT) | C12: MT | D12: =VLOOKUP(C12,Rascunho!$B$3:$C$29,2,FALSE) -> 0.17 | E12: =E11 -> 0.05 | F12: =((VLOOKUP($B12,'Tarifas e Resoluções'!$B$5:$M$44,2,FALSE)-VLOOKUP($B12,'Tarifas e Resoluções'!$B$5:$M$44,4,FALSE))*0.5)+VLOOKUP($B12,'Tarifas e Resoluções'!$B$5:$M$44,4,FALSE) -> 0.92217 | G12: =F12/(1-E12)/(1-D12)+((VLOOKUP($B12,'Tarifas e Resoluções'!$B$5:$M$44,2,FALSE)-F12)/(1-E12)/(1-D12)-(VLOOKUP($B12,'Tarifas e Resoluções'!$B$5:$M$44,2,FALSE)-F12)) -> 1.3817272 | H12: =IF(VLOOKUP($B12,'Tarifas e Resoluções'!$B$5:$M$44,7,FALSE)="","",((VLOOKUP($B12,'Tarifas e Resoluções'!$B$5:$M$44,7,FALSE)-VLOOKUP($B12,'Tarifas e Resoluções'!$B$5:$M$44,9,FALSE))*0.5)+VLOOKUP($B12,'Tarifas e Resoluções'!$B$5:$M$44,9,FALSE)) -> 0.98696 | I12: =IFERROR(H12/(1-E12)/(1-D12)+((VLOOKUP($B12,'Tarifas e Resoluções'!$B$5:$M$44,7,FALSE)-H12)/(1-E12)/(1-D12)-(VLOOKUP($B12,'Tarifas e Resoluções'!$B$5:$M$44,7,FALSE)-H12)),"") -> 1.471916 | J12: =IFERROR(I12/G12-1,"") -> 0.065272492 | L12: =VLOOKUP(N12,Rascunho!$I$4:$K$43,2,FALSE) -> Neoenergia BA (COELBA) | M12: =VLOOKUP(N12,Rascunho!$I$4:$K$43,3,FALSE) -> BA | N12: =LARGE(Rascunho!$I$4:$I$43,7) -> 2.0254475 | O12: 7
